Workbook
Name AER: 'GREECE Markowitz'!$R$2:$W$2
Name anscount: 22
Name comments: 'ΟΜΟΛΟΓΑ USA'!#REF!
Name COV: 'GREECE Markowitz'!$M$11:$R$16
Name COVij: 'GREECE Markowitz'!$M$20:$R$25
Name COVij: 'USA Markowitz'!$M$20:$R$25
Name ER: #REF!
Name n: #REF!
Name opap: ΧΑΑ!#REF!
Name R_1: #REF!
Name R_2: #REF!
Name Rij: #REF!
Name USaeg: 'USA Markowitz'!$R$2:$W$2
Name UScovij: 'USA Markowitz'!$M$20:$R$25
Name USw: 'USA Markowitz'!$T$20:$T$25
Name USwr: 'USA Markowitz'!$R$2:$W$2
Name v: 'GREECE Markowitz'!$T$20:$T$25
Name VarRm: 'GREECE Sharpe'!$D$27
Name VarRm: 'USA Sharpe'!$D$27
Name W: #REF!
Name w_c: #REF!
Name Wr: 'GREECE Markowitz'!$T$20:$T$25

Sheet Ερωτηματολόγιο
C1: ΑΝΑΛΥΣΗ ΠΡΟΦΙΛ ΕΠΕΝΔΥΤΟΥ
C2: ΕΡΩΤΗΜΑΤΟΛΟΓΙΟ
C4: ΟΔΗΓΙΕΣ: Παρακαλεισθε να σημειωσετε με ενα Χ την απαντηση η
C5: οποια αφορα την οικογενεια σας. Αφου γραψετε δε τον αριθμο στο
C6: κενο δεξια πρεπει να αθροισετε τους αριθμους και να διαιρεσετε το
C7: αθροισμα αυτο με το 9 (αριθμός ερωτήσεων). Ο μεσος αυτος θα σας δειξει τον
C8: βαθμό κινδυνου που σας χαρακρηριζει, σε μια κλιμακα κινδυνου απο 1
C9: (μικρος βαθμος αποφυγής κινδυνου ή επενδυτής υψηλου κινδυνου)
C10: εως 9 (υψηλος βαθμος αποφυγης κινδυνου ή επενδυτης χαμηλου κινδυνου).
C11: Με βαση τελος τoν βαθμο κινδυνου αυτο θα συγκροτηθει
C12: χαρτοφυλακιο επενδυσεως απο τιτλους χωρίς κινδυνο και με κίνδυνο
B14: A. | C14: ΗΛΙΚΙΑ - Η ηλικια μου ειναι πλησιεστερη στα:
C16: (1) 30 | D16: (3) 40 | E16: (5) 50 | F16: (7) 60 | G16: (9) 70
C18: ΑΠΑΝΤΗΣΗ | D18: [ | E18: 1 | F18: ]
B20: Β. | C20: ΕΙΣΟΔΗΜΑ - Το παρον ετησιο εισοδημα μου απο ολες τις πηγες
C21: σε χιλιάδες ευρώ ειναι:
C23: (2) 41 και ανω | D23: (4) 31-40 | E23: (5) 21-30 | F23: (6) 10-20 | G23: (8)6-9
C25: ΑΠΑΝΤΗΣΗ | D25: [ | E25: 2 | F25: ]
B27: Γ. | C27: ΕΤΗΣΙΑ ΕΞΟΔΑ - Σε σχεση με τα εσοδα μου τα εξοδα μου
C28: ανερχονται σε ποσοστο:
C30: (1) 40% | D30: (3) 70% | E30: (5) 80% | F30: (7) 90% | G30: (9)100%
C32: ΑΠΑΝΤΗΣΗ | D32: [ | E32: 3 | F32: ]
B34: Δ. | C34: ΑΡΙΘΜΟΣ ΕΞΑΡΤΟΝΕΝΩΝ ΜΕΛΩΝ ΟΙΚΟΓΕΝΕΙΑΣ - Προς το παρον εχω
C35: αυτα τα μελη οικογενειας που εξαρτωνται
C37: (1) 0 | D37: (4) 1 | E37: (6) 2-3 | F37: (8) 4-5 | G37: (9) 6
G38: και ανω
C39: ΑΠΑΝΤΗΣΗ | D39: [ | E39: 6 | F39: ]
B41: Ε. | C41: ΕΚΤΙΜΗΣΗ ΑΞΙΑΣ ΠΕΡΙΟΥΣΙΑΚΩΝ ΣΤΟΙΧΕΙΩΝ -
C42: Το σπιτιμου, οι καταθεσεις, οι επενδυσεις και η ασφαλιση μου
C43: αθροιζονται σε χιλιάδες ευρώ:
C45: (1) 151 και ανω | D45: (3) 91-150 | E45: (5) 51-90 | F45: (7) 16-50 | G45: (9) 15
C47: ΑΠΑΝΤΗΣΗ | D47: [ | E47: 1 | F47: ]
B49: Ζ. | C49: ΕΚΤΙΜΗΣΗ ΥΠΟΧΡΕΩΣΕΩΝ - ΟΙ βραχυπροθεσμες ωφειλες μου, τα
C50: τα ενυποθηκα δανεια, οι δοσεις και λοιπες ωφειλες
C51: σε σχεση με τα περιουσιακα μου στοιχεια
C53: (1) 30% | D53: (3) 50% | E53: (5) 75% | F53: (7) 90% | G53: (9) 100%
C55: ΑΠΑΝΤΗΣΗ | D55: [ | E55: 1 | F55: ]
B57: ΣΤ. | C57: ΑΠΟΤΑΜΙΕΥΣΕΙΣ - Εχω ρευστο, καταθεσεις η αλλα ρευστοποιησιμα
C58: περιουσιακα στοιχεια για καλυψη των παραπανω υποχρεωσεων:
C60: (1) 6 μηνες | D60: (3) 4 μηνες | E60: (5) 3 μηνες | F60: (7) 2 μηνες | G60: (9) 1 μηνα
...

Sheet Screenshots
B15: ΠΑΡΕΥΡΕΘΗΚΑ ΣΤΟ ΜΑΘΗΜΑ ΑΛΛΑ ΕΙΧΑ ΠΡΟΒΛΗΜΑ ΜΕ ΤΟ EXCEL ΟΠΟΤΕ ΤΟ ΟΛΟΚΛΗΡΩΣΑ ΜΕ ΑΛΛΟΝ ΥΠΟΛΟΓΙΣΤΗ ΤΗΝ ΕΠΟΜΕΝΗ ΜΕΡΑ

Sheet ΟΜΟΛΟΓΑ ΧΑΑ
A1: GREECE 10 YEAR BOND YIELD | B1: Date | C1: Price | D1: Open | E1: High | F1: Low | G1: Change % | J1: https://www.investing.com/rates-bonds/greece-10-year-bond-yield-historical-data
B2: 23/10/2025 | C2: 0.03242 | E2: 0.03257 | F2: 0.03229
B3: 45960 | C3: 0.03295 | E3: 0.03317 | F3: 0.03281 | I3: ΔΙΑΔΙΚΑΣΙΑ YΠΟΛΟΓΙΣΜΟΥ ΑΞΙΑΣ ΟΜOΛΟΓΩΝ και ΟΜΟΛΟΓΙΩΝ
B4: 45967 | C4: 0.0319 | E4: 0.03339 | F4: 0.03302 | I4: [ΖΗΤΟΥΜΕΝΟ Η ΤΙΜΗ ΠΩΛΗΣΗΣ]
B5: 45974 | C5: 0.03321 | E5: 0.0331 | F5: 0.03262 | O5: ΤΙΜΗ ΟΜΟΛΟΓΙΑΣ (ΥΠΟΘΕΤΟΥΜΕ ΣΤΗΝ ΟΝΟΜΑΣΤΙΚΗ ΑΞΙΑ ΤΗΝ ΗΜΕΡΟΜΗΝΙΑ ΑΓΟΡΑΣ 100%)
B6: 45981 | C6: 0.03351 | E6: 0.0389 | F6: 0.0334 | I6: V | J6: 1000 | K6: ΤΙΜΗ ΣΤΟ ΑΡΤΙΟ ή ΟΝΟΜΑΣΤΙΚΗ ΑΞΙΑ ΟΜΟΛΟΓΙΑΣ | L6: [Face Value or Par value]
B7: 45988 | C7: 0.0331 | E7: 0.0323 | F7: 0.03293 | I7: n | J7: 10 | K7: ΧΡΟΝΟΣ ΓΙΑ ΝΑ ΛΗΞΗ | L7: [Life to Maturity] | O7: ΕΠΙΤΟΚΙΟ-ΑΠΟΔΟΣΗ ΤΗΝ ΗΜΕΡΟΜΗΝΙΑ ΑΓΟΡΑΣ ΤΟΥ ΟΜΟΛΟΓΙΑΣ
I8: nm | J8: =J7*J9 -> 10 | O8: πχ ΕΔΩ 1/3/2018
I9: m | J9: 1 | K9: ΚΑΘΕ ΠΕΡΙΟΔΟΣ (1 ΕΤΟΣ, 2 ΕΞΑΜΗΜΟ, 12 ΜΗΝΕΣ) | L9: [every period] | O9: ΕΠΙΤΟΚΙΟ-ΑΠΟΔΟΣΗ ΤΗΝ ΗΜΕΡΟΜΗΝΙΑ ΑΠΟΤΙΜΗΣΗΣ ΤΟΥ ΟΜΟΛΟΓΟΥ
I10: Ct | J10: =J6*J11 -> 32.42 | K10: ΤΟΚΟΣ ΚΟΥΠΟΝΙΟΥ ΣΤΟ ΧΡΟΝΟ t | L10: [Coupon Interest] | O10: πχ ΕΔΏ 24/5/2018 | Q10: (ΑΡΓΟΤΕΡΑ ΗΜΕΡΟΜΗΝΙΑ ΡΕΥΣΤΟΠΟΙΗΣΗΣ ΧΑΡΤΟΦΥΛΑΚΙΟΥ Ή ΕΚΤΙΜΗΣΗΣ ΤΙΜΩΝ ΜΕΤΑ ΈΝΑ ΕΤΟΣ)
I11: %C | J11: =C2 -> 0.03242 | K11: ΕΠΙΤΟΚΙΟ ΚΟΥΠΟΝΙΟΥ | L11: [Coupon Rate]
I12: i | J12: =C3 -> 0.03295 | K12: ΕΠΙΤΟΚΙΟ ΑΓΟΡΑΣ | L12: [Market Rate]
I14: Pt | J14: =-PV(J12/J9,J8,J10,J6) -> 995.5463 | K14: ΚΑΘΑΡΗ ΤΙΜΗ ΑΓΟΡΑΣ | L14: [Bond Price]
J15: =J14/J6 -> 0.9955463 | K15: =IF(J14<J6,"ΥΠΟ ΤΟ ΑΡΤΙΟ",IF(J14>J6,"ΥΠΕΡ ΤΟ ΑΡΤΙΟ","ΣΤΟ ΑΡΤΙΟ")) -> ΥΠΟ ΤΟ ΑΡΤΙΟ
I17: ΑΝΑΛΥΤΙΚΑ
I18: ΠΛΗΡΩΜΕΣ ΠΕΡΙΟΔΟΥ (ΕΤΗΣΙΕΣ)
I19: ΠΑΡΟΥΣΑ ΑΞΙΑ ΤΟΚΟΜΕΡΙΔΙΩΝ
L20: ΠΑΡΟΥΣΑ ΑΞΙΑ ΤΙΜΗΣ ΚΑΤΑ ΤΗΝ ΛΗΞΗ
I21: ΡΟΕΣ | K21: PVIFA(r,n) | L21: ΡΟΕΣ | N21: PVIF(r,n)
I22: =J10 -> 32.42 | J22: x | K22: =PV(J12/J9,J8,-1) -> 8.4032054 | L22: =J6 -> 1000 | M22: x | N22: =1/(1+J12)^J8 -> 0.72311438
J23: =I22*K22 -> 272.43192 | M23: =L22*N22 -> 723.11438
J25: παρουσα αξια τοκομεριδιων | M25: =J23 -> 272.43192
J26: παρουσα αξια τιμης ληξης | M26: =M23 -> 723.11438
J28: αγοραια τιμη ομολ. | L28: Pt | M28: =M25+M26 -> 995.5463
J29: πωληση υπο(-), υπερ(+) το αρτιο | M29: =M28/J6 -> 0.9955463 | O29: ΤΙΜΗ ΟΜΟΛΟΓΙΑΣ ΤΗΝ ΗΜΕΡΟΜΗΝΙΑ ΑΠΟΤΙΜΗΣΗΣ ΤΟΥ ΟΜΟΛΟΓΟΥ
J30: απόδοση-στη-λήξη | O30: πχ ΕΔΏ 24/5/2018 | Q30: (ΑΡΓΟΤΕΡΑ ΗΜΕΡΟΜΗΝΙΑ ΡΕΥΣΤΟΠΟΙΗΣΗΣ ΧΑΡΤΟΦΥΛΑΚΙΟΥ Ή ΕΚΤΙΜΗΣΗΣ ΤΙΜΩΝ ΜΕΤΑ ΈΝΑ ΕΤΟΣ)
L34: ΥΠΟΛΟΓΙΣΜΟΣ ΤΙΜΗΣ ΟΜΟΛΟΓΙΑΣ
L37: ΥΠΟΛΟΓΙΣΜΟΣ ΑΠΟΔΟΣΗΣ ΣΤΗ ΛΗΞΗ

Sheet ΟΜΟΛΟΓΑ USA
A1: USA 10 YEAR BOND YIELD | B1: Date | C1: Price | D1: Open | E1: High | F1: Low | G1: Change % | I1: https://www.investing.com/rates-bonds/u.s.-10-year-bond-yield-historical-data
B2: 23/10/2025 | C2: 0.03983 | E2: 0.0397 | F2: 0.03949
B3: 45960 | C3: 0.04071 | E3: 0.04118 | F3: 0.0406 | I3: ΔΙΑΔΙΚΑΣΙΑ YΠΟΛΟΓΙΣΜΟΥ ΑΞΙΑΣ ΟΜOΛΟΓΩΝ και ΟΜΟΛΟΓΙΩΝ
B4: 45967 | C4: 0.04083 | E4: 0.04153 | F4: 0.04077 | I4: [ΖΗΤΟΥΜΕΝΟ Η ΤΙΜΗ ΠΩΛΗΣΗΣ]
B5: 45974 | C5: 0.04088 | E5: 0.04104 | F5: 0.04056 | O5: ΤΙΜΗ ΟΜΟΛΟΓΙΑΣ (ΥΠΟΘΕΤΟΥΜΕ ΣΤΗΝ ΟΝΟΜΑΣΤΙΚΗ ΑΞΙΑ ΤΗΝ ΗΜΕΡΟΜΗΝΙΑ ΑΓΟΡΑΣ 100%)
B6: 45981 | C6: 0.04098 | E6: 0.04168 | F6: 0.04094 | I6: V | J6: 1000 | K6: ΤΙΜΗ ΣΤΟ ΑΡΤΙΟ ή ΟΝΟΜΑΣΤΙΚΗ ΑΞΙΑ ΟΜΟΛΟΓΙΑΣ | L6: [Face Value or Par value]
B7: 45988 | C7: 0.04001 | E7: 0.04015 | F7: 0.03996 | I7: n | J7: 10 | K7: ΧΡΟΝΟΣ ΓΙΑ ΝΑ ΛΗΞΗ | L7: [Life to Maturity] | O7: ΕΠΙΤΟΚΙΟ-ΑΠΟΔΟΣΗ ΤΗΝ ΗΜΕΡΟΜΗΝΙΑ ΑΓΟΡΑΣ ΤΟΥ ΟΜΟΛΟΓΙΑΣ
I8: nm | J8: =J7*J9 -> 10 | O8: πχ ΕΔΏ 1/3/2018
I9: m | J9: 1 | K9: ΚΑΘΕ ΠΕΡΙΟΔΟΣ (1 ΕΤΟΣ, 2 ΕΞΑΜΗΜΟ, 12 ΜΗΝΕΣ) | L9: [every period] | O9: ΕΠΙΤΟΚΙΟ-ΑΠΟΔΟΣΗ ΤΗΝ ΗΜΕΡΟΜΗΝΙΑ ΑΠΟΤΙΜΗΣΗΣ ΤΟΥ ΟΜΟΛΟΓΟΥ
I10: Ct | J10: =J6*J11 -> 39.83 | K10: ΤΟΚΟΣ ΚΟΥΠΟΝΙΟΥ ΣΤΟ ΧΡΟΝΟ t | L10: [Coupon Interest] | O10: πχ ΕΔΏ 31/5/2017
I11: %C | J11: =C2 -> 0.03983 | K11: ΕΠΙΤΟΚΙΟ ΚΟΥΠΟΝΙΟΥ | L11: [Coupon Rate]
I12: i | J12: =C3 -> 0.04071 | K12: ΕΠΙΤΟΚΙΟ ΑΓΟΡΑΣ | L12: [Market Rate]
I14: Pt | J14: =-PV(J12/J9,J8,J10,J6) -> 992.88757 | K14: ΚΑΘΑΡΗ ΤΙΜΗ ΑΓΟΡΑΣ | L14: [Bond Price]
J15: =J14/J6 -> 0.99288757 | K15: =IF(J14<J6,"ΥΠΟ ΤΟ ΑΡΤΙΟ",IF(J14>J6,"ΥΠΕΡ ΤΟ ΑΡΤΙΟ","ΣΤΟ ΑΡΤΙΟ")) -> ΥΠΟ ΤΟ ΑΡΤΙΟ
I17: ΑΝΑΛΥΤΙΚΑ
I18: ΠΛΗΡΩΜΕΣ ΠΕΡΙΟΔΟΥ (ΕΤΗΣΙΕΣ)
I19: ΠΑΡΟΥΣΑ ΑΞΙΑ ΤΟΚΟΜΕΡΙΔΙΩΝ
L20: ΠΑΡΟΥΣΑ ΑΞΙΑ ΤΙΜΗΣ ΚΑΤΑ ΤΗΝ ΛΗΞΗ
I21: ΡΟΕΣ | K21: PVIFA(r,n) | L21: ΡΟΕΣ | N21: PVIF(r,n)
I22: =J10 -> 39.83 | J22: x | K22: =PV(J12/J9,J8,-1) -> 8.0823038 | L22: =J6 -> 1000 | M22: x | N22: =1/(1+J12/J9)^J8 -> 0.67096941
J23: =I22*K22 -> 321.91816 | M23: =L22*N22 -> 670.96941
J25: παρουσα αξια τοκομεριδιων | M25: =J23 -> 321.91816
J26: παρουσα αξια τιμης ληξης | M26: =M23 -> 670.96941
J28: αγοραια τιμη ομολ. | L28: Pt | M28: =M25+M26 -> 992.88757
J29: πωληση υπο(-), υπερ(+) το αρτιο | M29: =M28/J6 -> 0.99288757 | O29: ΤΙΜΗ ΟΜΟΛΟΓΙΑΣ ΤΗΝ ΗΜΕΡΟΜΗΝΙΑ ΑΠΟΤΙΜΗΣΗΣ ΤΟΥ ΟΜΟΛΟΓΟΥ
J30: απόδοση-στη-λήξη | O30: πχ ΕΔΏ 24/5/2018
L34: ΥΠΟΛΟΓΙΣΜΟΣ ΤΙΜΗΣ ΟΜΟΛΟΓΙΑΣ
L37: ΥΠΟΛΟΓΙΣΜΟΣ ΑΠΟΔΟΣΗΣ ΣΤΗ ΛΗΞΗ

Sheet Ομολογα
A1: 1 | B1: Spreads 10ετών κρατικών ομολόγων
B2: 23/10/2025
B3: ΣΕ ΕΤΗΣΙΑ ΒΑΣΗ
B4: Χώρα | C4: Απόδοση | D4: Spread έναντι Bund | E4: Spread έναντι T-bond
B5: Γερμανία | C5: 0.025782 | E5: =C5-C7 -> -0.014048 | H5: ETΗΣΙΟΠOIHMENO ΣΕ ΠΕΡΙΟΔΙΚΟ
B6: Ελλάδα | C6: 0.03242 | D6: =C6-C5 -> 0.006638 | E6: =C6-C7 -> -0.00741 | H6: ΙΣΧΥΕΙ Η ΣΧΕΣΗ
B7: ΗΠΑ | C7: 0.03983 | D7: =C7-C5 -> 0.014048
B9: n= Αριθμός Ετών | D9: 1
B10: m= περίοδοι ανα Ετος | D10: 250 | H10: R το Ετησιο Επιτοκιο
H11: r=R/m το Περιοδικο Επιτοκιο
B12: ΣΕ ΗΜΕΡΗΣΙΑ ΒΑΣΗ
B13: Χώρα | C13: Απόδοση | D13: Spread έναντι Bund | E13: Spread έναντι T-bond
B14: Γερμανία | C14: =(1+C5)^(1/($D$10*$D$9))-1 -> 0.00010182618 | E14: =(1+E5)^(1/($D$10*$D$9))-1 -> -5.6588827e-05
B15: Ελλάδα | C15: =(1+C6)^(1/($D$10*$D$9))-1 -> 0.00012763039 | D15: =(1+D6)^(1/($D$10*$D$9))-1 -> 2.6464612e-05 | E15: =(1+E6)^(1/($D$10*$D$9))-1 -> -2.9749919e-05
B16: ΗΠΑ | C16: =(1+C7)^(1/($D$10*$D$9))-1 -> 0.00015624116 | D16: =(1+D7)^(1/($D$10*$D$9))-1 -> 5.5802522e-05
B18: http://www.naftemporiki.gr/finance/spreads
B19: https://www.investing.com/rates-bonds/
A21: 2 | B21: EURIBOR
B22: 43160

Sheet Εκτίμηση Ομολόγου
A2: XAA | B2: ΔΙΑΔΙΚΑΣΙΑ YΠΟΛΟΓΙΣΜΟΥ ΑΞΙΑΣ ΟΜOΛΟΓΩΝ και ΟΜΟΛΟΓΙΩΝ
B3: [ΖΗΤΟΥΜΕΝΟ Η ΤΙΜΗ ΠΩΛΗΣΗΣ]
H4: ΤΙΜΗ ΟΜΟΛΟΓΙΑΣ (ΥΠΟΘΕΤΟΥΜΕ ΣΤΗΝ ΟΝΟΜΑΣΤΙΚΗ ΑΞΙΑ ΤΗΝ ΗΜΕΡΟΜΗΝΙΑ ΑΓΟΡΑΣ 100%)
B5: V | C5: 1000 | D5: ΤΙΜΗ ΣΤΟ ΑΡΤΙΟ ή ΟΝΟΜΑΣΤΙΚΗ ΑΞΙΑ ΟΜΟΛΟΓΙΑΣ | E5: [Face Value or Par value]
B6: n | C6: 10 | D6: ΧΡΟΝΟΣ ΓΙΑ ΝΑ ΛΗΞΗ | E6: [Life to Maturity] | H6: ΕΠΙΤΟΚΙΟ-ΑΠΟΔΟΣΗ ΤΗΝ ΗΜΕΡΟΜΗΝΙΑ ΑΓΟΡΑΣ ΤΟΥ ΟΜΟΛΟΓΟΥ
B7: nm | C7: =C6*C8 -> 10 | H7: πχ ΕΔΏ 16/5/2018
B8: m | C8: 1 | D8: ΚΑΘΕ ΠΕΡΙΟΔΟΣ (1 ΕΤΟΣ, 2 ΕΞΑΜΗΜΟ, 12 ΜΗΝΕΣ) | E8: [every period] | H8: ΕΠΙΤΟΚΙΟ-ΑΠΟΔΟΣΗ ΤΗΝ ΗΜΕΡΟΜΗΝΙΑ ΑΠΟΤΙΜΗΣΗΣ ΤΟΥ ΟΜΟΛΟΓΟΥ
B9: Ct | C9: =C5*C10 -> 33.51 | D9: ΤΟΚΟΣ ΚΟΥΠΟΝΙΟΥ ΣΤΟ ΧΡΟΝΟ t | E9: [Coupon Interest] | H9: πχ ΕΔΏ 16/5/2019
B10: %C | C10: ='ΟΜΟΛΟΓΑ ΧΑΑ'!C6 -> 0.03351 | D10: ΕΠΙΤΟΚΙΟ ΚΟΥΠΟΝΙΟΥ | E10: [Coupon Rate]
B11: i | C11: ='Forecasts Greece'!C20 -> 0 | D11: ΕΠΙΤΟΚΙΟ ΑΓΟΡΑΣ | E11: [Market Rate]
A13: XAA | B13: Pt | C13: =-PV(C11/C8,C7,C9,C5) -> 1335.1 | D13: ΚΑΘΑΡΗ ΤΙΜΗ ΑΓΟΡΑΣ | E13: [Bond Price]
C14: =C13/C5 -> 1.3351 | D14: =IF(C13<C5,"ΥΠΟ ΤΟ ΑΡΤΙΟ",IF(C13>C5,"ΥΠΕΡ ΤΟ ΑΡΤΙΟ","ΣΤΟ ΑΡΤΙΟ")) -> ΥΠΕΡ ΤΟ ΑΡΤΙΟ
B16: ΑΝΑΛΥΤΙΚΑ
B17: ΠΛΗΡΩΜΕΣ ΠΕΡΙΟΔΟΥ (ΕΤΗΣΙΕΣ)
B18: ΠΑΡΟΥΣΑ ΑΞΙΑ ΤΟΚΟΜΕΡΙΔΙΩΝ
E19: ΠΑΡΟΥΣΑ ΑΞΙΑ ΤΙΜΗΣ ΚΑΤΑ ΤΗΝ ΛΗΞΗ
B20: ΡΟΕΣ | D20: PVIFA(r,n) | E20: ΡΟΕΣ | G20: PVIF(r,n)
B21: =C9 -> 33.51 | C21: x | D21: =PV(C11/C8,C7,-1) -> 10 | E21: =C5 -> 1000 | F21: x | G21: =1/(1+C11/C8)^C7 -> 1
C22: =B21*D21 -> 335.1 | F22: =E21*G21 -> 1000
C24: παρουσα αξια τοκομεριδιων | F24: =C22 -> 335.1
C25: παρουσα αξια τιμης ληξης | F25: =F22 -> 1000
C27: αγοραια τιμη ομολ. | E27: Pt | F27: =F24+F25 -> 1335.1
A28: XAA | C28: πωληση υπο(-), υπερ(+) το αρτιο | F28: =F27/C5 -> 1.3351 | H28: ΤΙΜΗ ΟΜΟΛΟΓΙΑΣ ΤΗΝ ΗΜΕΡΟΜΗΝΙΑ ΑΠΟΤΙΜΗΣΗΣ ΤΟΥ ΟΜΟΛΟΓΟΥ
C29: απόδοση-στη-λήξη | H29: πχ ΕΔΏ 24/5/2019
A33: USA | B33: ΔΙΑΔΙΚΑΣΙΑ YΠΟΛΟΓΙΣΜΟΥ ΑΞΙΑΣ ΟΜOΛΟΓΩΝ και ΟΜΟΛΟΓΙΩΝ
B34: [ΖΗΤΟΥΜΕΝΟ Η ΤΙΜΗ ΠΩΛΗΣΗΣ]
H35: ΤΙΜΗ ΟΜΟΛΟΓΙΑΣ (ΥΠΟΘΕΤΟΥΜΕ ΣΤΗΝ ΟΝΟΜΑΣΤΙΚΗ ΑΞΙΑ ΤΗΝ ΗΜΕΡΟΜΗΝΙΑ ΑΓΟΡΑΣ 100%)
B36: V | C36: 1000 | D36: ΤΙΜΗ ΣΤΟ ΑΡΤΙΟ ή ΟΝΟΜΑΣΤΙΚΗ ΑΞΙΑ ΟΜΟΛΟΓΙΑΣ | E36: [Face Value or Par value]
B37: n | C37: 10 | D37: ΧΡΟΝΟΣ ΓΙΑ ΝΑ ΛΗΞΗ | E37: [Life to Maturity] | H37: ΕΠΙΤΟΚΙΟ-ΑΠΟΔΟΣΗ ΤΗΝ ΗΜΕΡΟΜΗΝΙΑ ΑΓΟΡΑΣ ΤΟΥ ΟΜΟΛΟΓΙΑΣ
B38: nm | C38: =C37*C39 -> 10 | H38: πχ ΕΔΏ 16/5/2018
B39: m | C39: 1 | D39: ΚΑΘΕ ΠΕΡΙΟΔΟΣ (1 ΕΤΟΣ, 2 ΕΞΑΜΗΜΟ, 12 ΜΗΝΕΣ) | E39: [every period] | H39: ΕΠΙΤΟΚΙΟ-ΑΠΟΔΟΣΗ ΤΗΝ ΗΜΕΡΟΜΗΝΙΑ ΑΠΟΤΙΜΗΣΗΣ ΤΟΥ ΟΜΟΛΟΓΟΥ
B40: Ct | C40: =C36*C41 -> 40.98 | D40: ΤΟΚΟΣ ΚΟΥΠΟΝΙΟΥ ΣΤΟ ΧΡΟΝΟ t | E40: [Coupon Interest] | H40: πχ ΕΔΏ 16/5/2019
B41: %C | C41: ='ΟΜΟΛΟΓΑ USA'!C6 -> 0.04098 | D41: ΕΠΙΤΟΚΙΟ ΚΟΥΠΟΝΙΟΥ | E41: [Coupon Rate]
B42: i | C42: ='Forecasts USA'!C20 -> 0 | D42: ΕΠΙΤΟΚΙΟ ΑΓΟΡΑΣ | E42: [Market Rate]
A44: USA | B44: Pt | C44: =-PV(C42/C39,C38,C40,C36) -> 1409.8 | D44: ΚΑΘΑΡΗ ΤΙΜΗ ΑΓΟΡΑΣ | E44: [Bond Price]
C45: =C44/C36 -> 1.4098 | D45: =IF(C44<C36,"ΥΠΟ ΤΟ ΑΡΤΙΟ",IF(C44>C36,"ΥΠΕΡ ΤΟ ΑΡΤΙΟ","ΣΤΟ ΑΡΤΙΟ")) -> ΥΠΕΡ ΤΟ ΑΡΤΙΟ
B47: ΑΝΑΛΥΤΙΚΑ
B48: ΠΛΗΡΩΜΕΣ ΠΕΡΙΟΔΟΥ (ΕΤΗΣΙΕΣ)
B49: ΠΑΡΟΥΣΑ ΑΞΙΑ ΤΟΚΟΜΕΡΙΔΙΩΝ
E50: ΠΑΡΟΥΣΑ ΑΞΙΑ ΤΙΜΗΣ ΚΑΤΑ ΤΗΝ ΛΗΞΗ
...

Sheet ΧΑΑ
C1: ATG | K1: OPAr | S1: AGNr | AA1: ACBr | AI1: HRMr | AQ1: MTLNr | AY1: EURBr
A2: Ημ/νία | B2: Τελευταία | C2: Άνοιγμα | D2: Υψηλό | E2: Χαμηλό | F2: Όγκος | G2: Αλλ.% | I2: Ημ/νία | J2: Τελευταία | K2: Άνοιγμα | L2: Υψηλό | M2: Χαμηλό | N2: Όγκος | O2: Αλλ.% | Q2: Ημ/νία | R2: Τελευταία | S2: Άνοιγμα | T2: Υψηλό | U2: Χαμηλό | V2: Όγκος | W2: Αλλ.% | Y2: Ημ/νία | Z2: Τελευταία | AA2: Άνοιγμα | AB2: Υψηλό | AC2: Χαμηλό | AD2: Όγκος | AE2: Αλλ.% | AG2: Ημ/νία | AH2: Τελευταία | AI2: Άνοιγμα | AJ2: Υψηλό | AK2: Χαμηλό | AL2: Όγκος | AM2: Αλλ.% | AO2: Ημ/νία | AP2: Τελευταία | AQ2: Άνοιγμα | AR2: Υψηλό | AS2: Χαμηλό | AT2: Όγκος | AU2: Αλλ.% | AW2: Ημ/νία | AX2: Τελευταία | AY2: Άνοιγμα | AZ2: Υψηλό | BA2: Χαμηλό | BB2: Όγκος | BC2: Αλλ.%
A3: 23.10.2024 | B3: 1407.14 | C3: 1418.39 | D3: 1419.95 | E3: 1405.39 | F3: 30,90M | G3: -0.0053 | I3: 23.10.2024 | J3: 15.76 | K3: 15.92 | L3: 15.95 | M3: 15.76 | N3: 305,19K | O3: -0.0044 | Q3: 23.10.2024 | R3: 10.34 | S3: 10.42 | T3: 10.42 | U3: 10.26 | V3: 46,27K | W3: 0.0039 | Y3: 23.10.2024 | Z3: 1.438 | AA3: 1.475 | AB3: 1.478 | AC3: 1.431 | AD3: 9,14M | AE3: -0.0191 | AG3: 22.10.2025 | AH3: 22.84 | AI3: 22.72 | AJ3: 22.96 | AK3: 22.64 | AL3: 113,10K | AM3: 0.0053 | AO3: 23.10.2024 | AP3: 32.9 | AQ3: 33.4 | AR3: 33.52 | AS3: 32.84 | AT3: 217,93K | AU3: -0.0108 | AW3: 23.10.2024 | AX3: 1.8905 | AY3: 1.958 | AZ3: 1.958 | BA3: 1.881 | BB3: 11,21M | BC3: -0.0305
A4: 24.10.2024 | B4: 1402.6 | C4: 1406.09 | D4: 1415.71 | E4: 1398.58 | F4: 30,38M | G4: -0.0032 | I4: 24.10.2024 | J4: 15.73 | K4: 15.76 | L4: 15.87 | M4: 15.72 | N4: 291,30K | O4: -0.0019 | Q4: 24.10.2024 | R4: 10.4 | S4: 10.25 | T4: 10.44 | U4: 10.25 | V4: 35,96K | W4: 0.0058 | Y4: 24.10.2024 | Z4: 1.413 | AA4: 1.438 | AB4: 1.447 | AC4: 1.412 | AD4: 6,74M | AE4: -0.017 | AG4: 21.10.2025 | AH4: 22.72 | AI4: 22.8 | AJ4: 22.92 | AK4: 22.5 | AL4: 100,18K | AM4: -0.0035 | AO4: 24.10.2024 | AP4: 33.26 | AQ4: 32.84 | AR4: 33.32 | AS4: 32.84 | AT4: 136,10K | AU4: 0.0109 | AW4: 24.10.2024 | AX4: 1.9 | AY4: 1.89 | AZ4: 1.9065 | BA4: 1.861 | BB4: 8,56M | BC4: 0.005
A5: 25.10.2024 | B5: 1390.25 | C5: 1401.71 | D5: 1404.54 | E5: 1387.42 | F5: 27,93M | G5: -0.0088 | I5: 25.10.2024 | J5: 15.67 | K5: 15.77 | L5: 15.85 | M5: 15.6 | N5: 575,33K | O5: -0.0038 | Q5: 25.10.2024 | R5: 10.15 | S5: 10.27 | T5: 10.44 | U5: 10.15 | V5: 24,20K | W5: -0.024 | Y5: 25.10.2024 | Z5: 1.401 | AA5: 1.411 | AB5: 1.421 | AC5: 1.391 | AD5: 6,01M | AE5: -0.0092 | AG5: 20.10.2025 | AH5: 22.8 | AI5: 22.8 | AJ5: 23.04 | AK5: 22.5 | AL5: 83,05K | AM5: 0 | AO5: 25.10.2024 | AP5: 32.3 | AQ5: 33.26 | AR5: 33.3 | AS5: 32.3 | AT5: 224,18K | AU5: -0.0289 | AW5: 25.10.2024 | AX5: 1.88 | AY5: 1.9 | AZ5: 1.9 | BA5: 1.845 | BB5: 5,63M | BC5: -0.0105
A6: 29.10.2024 | B6: 1401.18 | C6: 1397.45 | D6: 1409.71 | E6: 1397.45 | F6: 51,64M | G6: 0.0079 | I6: 29.10.2024 | J6: 15.78 | K6: 15.88 | L6: 15.9 | M6: 15.67 | N6: 387,31K | O6: 0.007 | Q6: 29.10.2024 | R6: 10.13 | S6: 10.26 | T6: 10.3 | U6: 10.1 | V6: 55,59K | W6: -0.002 | Y6: 29.10.2024 | Z6: 1.422 | AA6: 1.425 | AB6: 1.443 | AC6: 1.413 | AD6: 26,92M | AE6: 0.0154 | AG6: 17.10.2025 | AH6: 22.8 | AI6: 23.08 | AJ6: 23.08 | AK6: 22.24 | AL6: 349,02K | AM6: -0.013 | AO6: 29.10.2024 | AP6: 32.4 | AQ6: 32.68 | AR6: 33.12 | AS6: 32.38 | AT6: 190,93K | AU6: 0.0031 | AW6: 29.10.2024 | AX6: 1.928 | AY6: 1.89 | AZ6: 1.9295 | BA6: 1.89 | BB6: 6,40M | BC6: 0.0255
A7: 30.10.2024 | B7: 1381.83 | C7: 1402.33 | D7: 1402.77 | E7: 1377.23 | F7: 31,21M | G7: -0.0138 | I7: 30.10.2024 | J7: 15.52 | K7: 15.78 | L7: 15.83 | M7: 15.52 | N7: 290,37K | O7: -0.0165 | Q7: 30.10.2024 | R7: 9.93 | S7: 10.11 | T7: 10.2 | U7: 9.9 | V7: 74,26K | W7: -0.0197 | Y7: 30.10.2024 | Z7: 1.37 | AA7: 1.42 | AB7: 1.434 | AC7: 1.37 | AD7: 7,38M | AE7: -0.0366 | AG7: 16.10.2025 | AH7: 23.1 | AI7: 23.42 | AJ7: 23.42 | AK7: 22.64 | AL7: 196,70K | AM7: -0.0137 | AO7: 30.10.2024 | AP7: 32.8 | AQ7: 32.4 | AR7: 32.8 | AS7: 31.84 | AT7: 347,25K | AU7: 0.0123 | AW7: 30.10.2024 | AX7: 1.901 | AY7: 1.936 | AZ7: 1.9385 | BA7: 1.871 | BB7: 8,64M | BC7: -0.014
A8: 31.10.2024 | B8: 1382.68 | C8: 1382.09 | D8: 1392.41 | E8: 1378.36 | F8: 32,63M | G8: 0.0006 | I8: 31.10.2024 | J8: 15.68 | K8: 15.6 | L8: 15.84 | M8: 15.6 | N8: 457,05K | O8: 0.0103 | Q8: 31.10.2024 | R8: 9.97 | S8: 9.93 | T8: 10 | U8: 9.9 | V8: 60,12K | W8: 0.0035 | Y8: 31.10.2024 | Z8: 1.38 | AA8: 1.375 | AB8: 1.398 | AC8: 1.367 | AD8: 6,70M | AE8: 0.0069 | AG8: 15.10.2025 | AH8: 23.42 | AI8: 23.5 | AJ8: 23.52 | AK8: 23.26 | AL8: 198,08K | AM8: 0.0009 | AO8: 31.10.2024 | AP8: 32.06 | AQ8: 32.42 | AR8: 32.8 | AS8: 32.06 | AT8: 299,04K | AU8: -0.0226 | AW8: 31.10.2024 | AX8: 1.89 | AY8: 1.9 | AZ8: 1.9175 | BA8: 1.8775 | BB8: 7,17M | BC8: -0.0058
A9: 01.11.2024 | B9: 1390.49 | C9: 1383.89 | D9: 1396 | E9: 1383.89 | F9: 27,55M | G9: 0.0056 | I9: 01.11.2024 | J9: 15.69 | K9: 15.75 | L9: 15.81 | M9: 15.68 | N9: 380,56K | O9: 0.0006 | Q9: 01.11.2024 | R9: 9.9 | S9: 9.93 | T9: 10.1 | U9: 9.9 | V9: 28,59K | W9: -0.0065 | Y9: 01.11.2024 | Z9: 1.401 | AA9: 1.39 | AB9: 1.422 | AC9: 1.39 | AD9: 5,53M | AE9: 0.0152 | AG9: 14.10.2025 | AH9: 23.4 | AI9: 23.36 | AJ9: 23.44 | AK9: 23.12 | AL9: 145,35K | AM9: 0.0017 | AO9: 01.11.2024 | AP9: 32.04 | AQ9: 32.4 | AR9: 32.44 | AS9: 32.04 | AT9: 159,98K | AU9: -0.0006 | AW9: 01.11.2024 | AX9: 1.919 | AY9: 1.882 | AZ9: 1.9285 | BA9: 1.882 | BB9: 6,21M | BC9: 0.0153 | BF9: =AZ9+AZ8 -> 3.846
A10: 04.11.2024 | B10: 1390.65 | C10: 1386.72 | D10: 1392.09 | E10: 1385.63 | F10: 15,31M | G10: 0.0001 | I10: 04.11.2024 | J10: 15.25 | K10: 15.35 | L10: 15.35 | M10: 15.19 | N10: 270,60K | O10: -0.028 | Q10: 04.11.2024 | R10: 9.76 | S10: 9.9 | T10: 10.08 | U10: 9.73 | V10: 47,64K | W10: -0.0146 | Y10: 04.11.2024 | Z10: 1.401 | AA10: 1.401 | AB10: 1.414 | AC10: 1.392 | AD10: 2,30M | AE10: 0 | AG10: 13.10.2025 | AH10: 23.36 | AI10: 22.72 | AJ10: 23.6 | AK10: 22.72 | AL10: 283,42K | AM10: 0.0165 | AO10: 04.11.2024 | AP10: 31.94 | AQ10: 32 | AR10: 32.2 | AS10: 31.62 | AT10: 191,73K | AU10: -0.0031 | AW10: 04.11.2024 | AX10: 1.94 | AY10: 1.8915 | AZ10: 1.948 | BA10: 1.8915 | BB10: 4,15M | BC10: 0.0109
A11: 05.11.2024 | B11: 1399.66 | C11: 1391.86 | D11: 1399.73 | E11: 1391.66 | F11: 29,20M | G11: 0.0065 | I11: 05.11.2024 | J11: 15.28 | K11: 15.25 | L11: 15.31 | M11: 15.1 | N11: 251,11K | O11: 0.002 | Q11: 05.11.2024 | R11: 9.8 | S11: 9.72 | T11: 9.86 | U11: 9.7 | V11: 21,50K | W11: 0.0046 | Y11: 05.11.2024 | Z11: 1.414 | AA11: 1.401 | AB11: 1.433 | AC11: 1.401 | AD11: 4,40M | AE11: 0.0096 | AG11: 10.10.2025 | AH11: 22.98 | AI11: 23 | AJ11: 23.02 | AK11: 22.8 | AL11: 132,96K | AM11: 0.0017 | AO11: 05.11.2024 | AP11: 32.1 | AQ11: 32 | AR11: 32.34 | AS11: 31.92 | AT11: 151,45K | AU11: 0.005 | AW11: 05.11.2024 | AX11: 1.97 | AY11: 1.948 | AZ11: 1.97 | BA11: 1.9405 | BB11: 3,80M | BC11: 0.0155
A12: 06.11.2024 | B12: 1408.57 | C12: 1412.85 | D12: 1424.79 | E12: 1406.12 | F12: 34,61M | G12: 0.0064 | I12: 06.11.2024 | J12: 15.1 | K12: 15.34 | L12: 15.39 | M12: 15.1 | N12: 247,89K | O12: -0.0118 | Q12: 06.11.2024 | R12: 9.79 | S12: 9.8 | T12: 10 | U12: 9.79 | V12: 39,49K | W12: -0.001 | Y12: 06.11.2024 | Z12: 1.431 | AA12: 1.45 | AB12: 1.465 | AC12: 1.431 | AD12: 9,22M | AE12: 0.0117 | AG12: 09.10.2025 | AH12: 22.94 | AI12: 22.68 | AJ12: 23.06 | AK12: 22.52 | AL12: 138,94K | AM12: 0.0187 | AO12: 06.11.2024 | AP12: 32.2 | AQ12: 32.56 | AR12: 32.64 | AS12: 32.2 | AT12: 205,99K | AU12: 0.0031 | AW12: 06.11.2024 | AX12: 1.9915 | AY12: 2 | AZ12: 2.038 | BA12: 1.991 | BB12: 5,32M | BC12: 0.0109
A13: 07.11.2024 | B13: 1408.5 | C13: 1408.79 | D13: 1412.73 | E13: 1404.77 | F13: 19,72M | G13: 0 | I13: 07.11.2024 | J13: 15.1 | K13: 15.1 | L13: 15.2 | M13: 15.02 | N13: 589,82K | O13: 0 | Q13: 07.11.2024 | R13: 9.8 | S13: 9.73 | T13: 9.85 | U13: 9.73 | V13: 21,81K | W13: 0.001 | Y13: 07.11.2024 | Z13: 1.426 | AA13: 1.431 | AB13: 1.447 | AC13: 1.423 | AD13: 3,14M | AE13: -0.0038 | AG13: 08.10.2025 | AH13: 22.52 | AI13: 22.48 | AJ13: 22.62 | AK13: 22.14 | AL13: 149,72K | AM13: 0.0018 | AO13: 07.11.2024 | AP13: 32.1 | AQ13: 32.32 | AR13: 32.4 | AS13: 31.96 | AT13: 130,47K | AU13: -0.0031 | AW13: 07.11.2024 | AX13: 1.988 | AY13: 1.987 | AZ13: 2.02 | BA13: 1.984 | BB13: 3,18M | BC13: -0.0018
A14: 08.11.2024 | B14: 1413.13 | C14: 1408.42 | D14: 1415.83 | E14: 1408.42 | F14: 43,10M | G14: 0.0033 | I14: 08.11.2024 | J14: 15.06 | K14: 15.1 | L14: 15.11 | M14: 15 | N14: 206,39K | O14: -0.0026 | Q14: 08.11.2024 | R14: 9.85 | S14: 9.7 | T14: 9.87 | U14: 9.67 | V14: 43,93K | W14: 0.0046 | Y14: 08.11.2024 | Z14: 1.502 | AA14: 1.426 | AB14: 1.505 | AC14: 1.426 | AD14: 14,66M | AE14: 0.0537 | AG14: 07.10.2025 | AH14: 22.48 | AI14: 22.26 | AJ14: 22.48 | AK14: 21.66 | AL14: 86,10K | AM14: 0.0172 | AO14: 08.11.2024 | AP14: 32.58 | AQ14: 32.1 | AR14: 32.88 | AS14: 31.96 | AT14: 117,96K | AU14: 0.015 | AW14: 08.11.2024 | AX14: 2.045 | AY14: 2.01 | AZ14: 2.05 | BA14: 2.01 | BB14: 13,70M | BC14: 0.0287
A15: 11.11.2024 | B15: 1428.4 | C15: 1415.42 | D15: 1428.4 | E15: 1415.42 | F15: 37,97M | G15: 0.0108 | I15: 11.11.2024 | J15: 15.13 | K15: 15.06 | L15: 15.24 | M15: 15.06 | N15: 430,45K | O15: 0.0046 | Q15: 11.11.2024 | R15: 10.02 | S15: 9.85 | T15: 10.09 | U15: 9.85 | V15: 60,50K | W15: 0.0178 | Y15: 11.11.2024 | Z15: 1.574 | AA15: 1.51 | AB15: 1.578 | AC15: 1.505 | AD15: 14,05M | AE15: 0.0476 | AG15: 06.10.2025 | AH15: 22.1 | AI15: 22.6 | AJ15: 22.7 | AK15: 22.08 | AL15: 100,63K | AM15: -0.0221 | AO15: 11.11.2024 | AP15: 33.22 | AQ15: 32.5 | AR15: 33.26 | AS15: 32.42 | AT15: 223,14K | AU15: 0.0196 | AW15: 11.11.2024 | AX15: 2.035 | AY15: 2.041 | AZ15: 2.06 | BA15: 2.029 | BB15: 12,31M | BC15: -0.0049
A16: 12.11.2024 | B16: 1430.91 | C16: 1426.18 | D16: 1434.28 | E16: 1422.02 | F16: 38,16M | G16: 0.0018 | I16: 12.11.2024 | J16: 15.1 | K16: 15.1 | L16: 15.15 | M16: 15.07 | N16: 656,06K | O16: -0.002 | Q16: 12.11.2024 | R16: 9.9 | S16: 10 | T16: 10.06 | U16: 9.9 | V16: 43,10K | W16: -0.012 | Y16: 12.11.2024 | Z16: 1.62 | AA16: 1.566 | AB16: 1.623 | AC16: 1.562 | AD16: 16,81M | AE16: 0.0292 | AG16: 03.10.2025 | AH16: 22.6 | AI16: 22.68 | AJ16: 22.72 | AK16: 22.4 | AL16: 113,99K | AM16: 0.008 | AO16: 12.11.2024 | AP16: 33 | AQ16: 33.2 | AR16: 33.2 | AS16: 32.82 | AT16: 132,86K | AU16: -0.0066 | AW16: 12.11.2024 | AX16: 2.034 | AY16: 2.03 | AZ16: 2.045 | BA16: 2.02 | BB16: 5,09M | BC16: -0.0005
A17: 13.11.2024 | B17: 1419.51 | C17: 1428.39 | D17: 1430.83 | E17: 1414.99 | F17: 36,87M | G17: -0.008 | I17: 13.11.2024 | J17: 15 | K17: 15.1 | L17: 15.15 | M17: 14.97 | N17: 532,19K | O17: -0.0066 | Q17: 13.11.2024 | R17: 9.8 | S17: 9.9 | T17: 9.91 | U17: 9.78 | V17: 24,49K | W17: -0.0101 | Y17: 13.11.2024 | Z17: 1.605 | AA17: 1.595 | AB17: 1.627 | AC17: 1.583 | AD17: 16,07M | AE17: -0.0093 | AG17: 02.10.2025 | AH17: 22.42 | AI17: 22.78 | AJ17: 22.78 | AK17: 22.18 | AL17: 98,51K | AM17: -0.008 | AO17: 13.11.2024 | AP17: 32.98 | AQ17: 33 | AR17: 33.04 | AS17: 32.5 | AT17: 139,09K | AU17: -0.0006 | AW17: 13.11.2024 | AX17: 2 | AY17: 2.018 | AZ17: 2.03 | BA17: 1.99 | BB17: 5,49M | BC17: -0.0167
A18: 14.11.2024 | B18: 1417.5 | C18: 1419.39 | D18: 1421 | E18: 1414.47 | F18: 32,76M | G18: -0.0014 | I18: 14.11.2024 | J18: 15.09 | K18: 15.07 | L18: 15.31 | M18: 14.98 | N18: 641,00K | O18: 0.006 | Q18: 14.11.2024 | R18: 9.85 | S18: 9.8 | T18: 9.92 | U18: 9.8 | V18: 22,16K | W18: 0.0051 | Y18: 14.11.2024 | Z18: 1.607 | AA18: 1.605 | AB18: 1.618 | AC18: 1.588 | AD18: 7,44M | AE18: 0.0012 | AG18: 01.10.2025 | AH18: 22.6 | AI18: 22.5 | AJ18: 22.64 | AK18: 22.34 | AL18: 89,13K | AM18: 0.0116 | AO18: 14.11.2024 | AP18: 33.2 | AQ18: 33.16 | AR18: 33.2 | AS18: 32.6 | AT18: 178,24K | AU18: 0.0067 | AW18: 14.11.2024 | AX18: 1.9715 | AY18: 2 | AZ18: 2.02 | BA18: 1.964 | BB18: 12,18M | BC18: -0.0142
A19: 15.11.2024 | B19: 1403.87 | C19: 1414.59 | D19: 1414.59 | E19: 1403.23 | F19: 33,59M | G19: -0.0096 | I19: 15.11.2024 | J19: 15.14 | K19: 15 | L19: 15.14 | M19: 14.92 | N19: 348,81K | O19: 0.0033 | Q19: 15.11.2024 | R19: 9.69 | S19: 9.9 | T19: 9.9 | U19: 9.6 | V19: 107,83K | W19: -0.0162 | Y19: 15.11.2024 | Z19: 1.579 | AA19: 1.584 | AB19: 1.6 | AC19: 1.561 | AD19: 7,31M | AE19: -0.0171 | AG19: 30.09.2025 | AH19: 22.34 | AI19: 22.8 | AJ19: 22.92 | AK19: 22.16 | AL19: 123,30K | AM19: -0.021 | AO19: 15.11.2024 | AP19: 33 | AQ19: 32.82 | AR19: 33.12 | AS19: 32.76 | AT19: 116,89K | AU19: -0.006 | AW19: 15.11.2024 | AX19: 1.97 | AY19: 1.97 | AZ19: 1.98 | BA19: 1.9545 | BB19: 13,91M | BC19: -0.0008
A20: 18.11.2024 | B20: 1392.44 | C20: 1399.93 | D20: 1401.06 | E20: 1381.7 | F20: 29,34M | G20: -0.0081 | I20: 18.11.2024 | J20: 14.98 | K20: 15.14 | L20: 15.14 | M20: 14.91 | N20: 214,43K | O20: -0.0106 | Q20: 18.11.2024 | R20: 9.53 | S20: 9.6 | T20: 9.6 | U20: 9.43 | V20: 82,73K | W20: -0.0165 | Y20: 18.11.2024 | Z20: 1.564 | AA20: 1.564 | AB20: 1.569 | AC20: 1.52 | AD20: 8,20M | AE20: -0.0095 | AG20: 29.09.2025 | AH20: 22.82 | AI20: 22.5 | AJ20: 23.06 | AK20: 22.4 | AL20: 134,68K | AM20: 0.0133 | AO20: 18.11.2024 | AP20: 32.32 | AQ20: 32.64 | AR20: 32.66 | AS20: 32.14 | AT20: 123,55K | AU20: -0.0206 | AW20: 18.11.2024 | AX20: 2.006 | AY20: 1.97 | AZ20: 2.006 | BA20: 1.925 | BB20: 6,90M | BC20: 0.0183
A21: 19.11.2024 | B21: 1366.72 | C21: 1392.5 | D21: 1397.53 | E21: 1359.95 | F21: 35,36M | G21: -0.0185 | I21: 19.11.2024 | J21: 14.85 | K21: 15.07 | L21: 15.07 | M21: 14.67 | N21: 395,59K | O21: -0.0087 | Q21: 19.11.2024 | R21: 9.23 | S21: 9.5 | T21: 9.59 | U21: 9.07 | V21: 129,38K | W21: -0.032 | Y21: 19.11.2024 | Z21: 1.537 | AA21: 1.577 | AB21: 1.577 | AC21: 1.495 | AD21: 9,09M | AE21: -0.0173 | AG21: 26.09.2025 | AH21: 22.52 | AI21: 22.3 | AJ21: 22.62 | AK21: 22.06 | AL21: 58,95K | AM21: 0.0099 | AO21: 19.11.2024 | AP21: 30.74 | AQ21: 32.2 | AR21: 32.42 | AS21: 30.7 | AT21: 360,42K | AU21: -0.0489 | AW21: 19.11.2024 | AX21: 1.977 | AY21: 2 | AZ21: 2.009 | BA21: 1.9535 | BB21: 6,56M | BC21: -0.0145
... A247: 17.10.2025 | B247: 1987.52 | C247: 1988.99 | D247: 1990.37 | E247: 1948.59 | F247: 69,29M | G247: -0.013 | I247: 17.10.2025 | J247: 17.97 | K247: 17.55 | L247: 18.03 | M247: 17.33 | N247: 2,43M | O247: 0.0164 | Q247: 17.10.2025 | R247: 13.24 | S247: 13.18 | T247: 13.32 | U247: 12.92 | V247: 216,12K | W247: -0.0105 | Y247: 22.10.2025 | Z247: 3.526 | AA247: 3.462 | AB247: 3.568 | AC247: 3.46 | AD247: 8,72M | AE247: 0.0176 | AG247: 29.10.2024 | AH247: 17.46 | AI247: 17.48 | AJ247: 17.62 | AK247: 17.46 | AL247: 71,74K | AM247: -0.0011 | AO247: 17.10.2025 | AP247: 42.56 | AQ247: 41.96 | AR247: 42.82 | AS247: 41.24 | AT247: 560,05K | AU247: -0.0019 | AW247: 17.10.2025 | AX247: 3.401 | AY247: 3.4 | AZ247: 3.417 | BA247: 3.304 | BB247: 14,05M | BC247: -0.0283
A248: 20.10.2025 | B248: 1996.23 | C248: 2009.67 | D248: 2023.26 | E248: 1989.91 | F248: 44,45M | G248: 0.0044 | I248: 20.10.2025 | J248: 18.06 | K248: 17.97 | L248: 18.22 | M248: 17.95 | N248: 747,53K | O248: 0.005 | Q248: 20.10.2025 | R248: 13.34 | S248: 13.24 | T248: 13.44 | U248: 13.2 | V248: 66,10K | W248: 0.0076 | AG248: 25.10.2024 | AH248: 17.48 | AI248: 17.44 | AJ248: 17.58 | AK248: 17.24 | AL248: 71,33K | AM248: -0.0011 | AO248: 20.10.2025 | AP248: 41.9 | AQ248: 43.02 | AR248: 43.18 | AS248: 41.4 | AT248: 403,05K | AU248: -0.0155 | AW248: 20.10.2025 | AX248: 3.39 | AY248: 3.45 | AZ248: 3.497 | BA248: 3.347 | BB248: 9,81M | BC248: -0.0032
A249: 21.10.2025 | B249: 2019.25 | C249: 1994.55 | D249: 2028.15 | E249: 1991.87 | F249: 36,28M | G249: 0.0115 | I249: 21.10.2025 | J249: 18.14 | K249: 18.03 | L249: 18.4 | M249: 18.03 | N249: 1,04M | O249: 0.0044 | Q249: 21.10.2025 | R249: 13.46 | S249: 13.36 | T249: 13.5 | U249: 13.28 | V249: 112,55K | W249: 0.009 | AG249: 24.10.2024 | AH249: 17.5 | AI249: 17.36 | AJ249: 17.52 | AK249: 17.24 | AL249: 50,40K | AM249: 0.0081 | AO249: 21.10.2025 | AP249: 42.84 | AQ249: 41.98 | AR249: 43.3 | AS249: 41.7 | AT249: 319,65K | AU249: 0.0224 | AW249: 21.10.2025 | AX249: 3.426 | AY249: 3.399 | AZ249: 3.461 | BA249: 3.39 | BB249: 5,36M | BC249: 0.0106
A250: 22.10.2025 | B250: 2033.97 | C250: 2026.38 | D250: 2038.14 | E250: 2021.2 | F250: 30,27M | G250: 0.0073 | I250: 22.10.2025 | J250: 18.42 | K250: 18.5 | L250: 18.71 | M250: 18.22 | N250: 870,67K | O250: 0.0154 | Q250: 22.10.2025 | R250: 13.52 | S250: 13.46 | T250: 13.58 | U250: 13.36 | V250: 79,62K | W250: 0.0045 | AG250: 23.10.2024 | AH250: 17.36 | AI250: 17.46 | AJ250: 17.46 | AK250: 17.16 | AL250: 47,08K | AM250: -0.0046 | AO250: 22.10.2025 | AP250: 44.04 | AQ250: 43.42 | AR250: 44.26 | AS250: 43.2 | AT250: 315,25K | AU250: 0.028 | AW250: 22.10.2025 | AX250: 3.463 | AY250: 3.475 | AZ250: 3.488 | BA250: 3.436 | BB250: 3,99M | BC250: 0.0108

Sheet Αμοιβαία

Sheet NYSE
C1: DOW JONES | K1: V | S1: JNJ | AA1: KO
A2: Ημ/νία | B2: Τελευταία | C2: Άνοιγμα | D2: Υψηλό | E2: Χαμηλό | F2: Όγκος | G2: Αλλ.% | I2: Ημ/νία | J2: Τελευταία | K2: Άνοιγμα | L2: Υψηλό | M2: Χαμηλό | N2: Όγκος | O2: Αλλ.% | Q2: Ημ/νία | R2: Τελευταία | S2: Άνοιγμα | T2: Υψηλό | U2: Χαμηλό | V2: Όγκος | W2: Αλλ.% | Y2: Ημ/νία | Z2: Τελευταία | AA2: Άνοιγμα | AB2: Υψηλό | AC2: Χαμηλό | AD2: Όγκος | AE2: Αλλ.%
A3: 23.10.2024 | B3: 42514.95 | C3: 42834.4 | D3: 42834.4 | E3: 42293.17 | F3: 356,62M | G3: -0.0096 | I3: 23.10.2024 | J3: 283.76 | K3: 286.04 | L3: 286.05 | M3: 283.53 | N3: 5,25M | O3: -0.0036 | Q3: 23.10.2024 | R3: 165.86 | S3: 162.82 | T3: 166 | U3: 162.42 | V3: 7,44M | W3: 0.0147 | Y3: 23.10.2024 | Z3: 68.01 | AA3: 66.99 | AB3: 68.7 | AC3: 66.58 | AD3: 24,66M | AE3: -0.0207
A4: 24.10.2024 | B4: 42374.36 | C4: 42522.55 | D4: 42522.55 | E4: 42191.83 | F4: 282,68M | G4: -0.0033 | I4: 24.10.2024 | J4: 283.22 | K4: 282.39 | L4: 283.62 | M4: 281.73 | N4: 4,68M | O4: -0.0019 | Q4: 24.10.2024 | R4: 163.67 | S4: 165 | T4: 165.51 | U4: 163.34 | V4: 5,39M | W4: -0.0132 | Y4: 24.10.2024 | Z4: 67.3 | AA4: 67.65 | AB4: 68.04 | AC4: 66.95 | AD4: 17,57M | AE4: -0.0104
A5: 25.10.2024 | B5: 42114.4 | C5: 42477.51 | D5: 42594.64 | E5: 42051.39 | F5: 314,00M | G5: -0.0061 | I5: 25.10.2024 | J5: 281.73 | K5: 284 | L5: 285.09 | M5: 280.78 | N5: 4,46M | O5: -0.0053 | Q5: 25.10.2024 | R5: 160.88 | S5: 163.68 | T5: 163.92 | U5: 160.61 | V5: 6,40M | W5: -0.017 | Y5: 25.10.2024 | Z5: 66.92 | AA5: 67.07 | AB5: 67.7 | AC5: 66.79 | AD5: 11,14M | AE5: -0.0056
A6: 28.10.2024 | B6: 42387.57 | C6: 42264.54 | D6: 42476.46 | E6: 42264.54 | F6: 284,78M | G6: 0.0065 | I6: 28.10.2024 | J6: 284.19 | K6: 282.04 | L6: 284.64 | M6: 281.53 | N6: 4,31M | O6: 0.0087 | Q6: 28.10.2024 | R6: 161.6 | S6: 161.13 | T6: 161.97 | U6: 161 | V6: 4,84M | W6: 0.0045 | Y6: 28.10.2024 | Z6: 66.67 | AA6: 66.96 | AB6: 67.39 | AC6: 66.6 | AD6: 10,76M | AE6: -0.0037
A7: 29.10.2024 | B7: 42233.05 | C7: 42323.48 | D7: 42491.86 | E7: 42171.65 | F7: 373,55M | G7: -0.0036 | I7: 29.10.2024 | J7: 281.88 | K7: 284.27 | L7: 285.7 | M7: 281.35 | N7: 7,53M | O7: -0.0081 | Q7: 29.10.2024 | R7: 160.09 | S7: 161.46 | T7: 162.17 | U7: 160.06 | V7: 5,22M | W7: -0.0093 | Y7: 29.10.2024 | Z7: 65.56 | AA7: 66.29 | AB7: 66.34 | AC7: 65.52 | AD7: 16,53M | AE7: -0.0166
A8: 30.10.2024 | B8: 42141.54 | C8: 42249.81 | D8: 42457.92 | E8: 42141.54 | F8: 377,43M | G8: -0.0022 | I8: 30.10.2024 | J8: 290.16 | K8: 292.34 | L8: 295.78 | M8: 288.33 | N8: 9,61M | O8: 0.0294 | Q8: 30.10.2024 | R8: 160.61 | S8: 159.45 | T8: 161.28 | U8: 159.03 | V8: 5,82M | W8: 0.0032 | Y8: 30.10.2024 | Z8: 65.92 | AA8: 65.51 | AB8: 66.54 | AC8: 65.32 | AD8: 14,18M | AE8: 0.0055
A9: 31.10.2024 | B9: 41763.46 | C9: 41956.34 | D9: 41991.91 | E9: 41704.63 | F9: 523,87M | G9: -0.009 | I9: 31.10.2024 | J9: 289.85 | K9: 292.09 | L9: 296.34 | M9: 289.62 | N9: 7,95M | O9: -0.0011 | Q9: 31.10.2024 | R9: 159.86 | S9: 159.99 | T9: 160.87 | U9: 159.46 | V9: 8,61M | W9: -0.0047 | Y9: 31.10.2024 | Z9: 65.31 | AA9: 65.81 | AB9: 65.99 | AC9: 65.25 | AD9: 13,38M | AE9: -0.0093
A10: 01.11.2024 | B10: 42052.19 | C10: 41869.82 | D10: 42326.31 | E10: 41869.82 | F10: 531,36M | G10: 0.0069 | I10: 01.11.2024 | J10: 290.74 | K10: 288.49 | L10: 292.67 | M10: 287.19 | N10: 5,47M | O10: 0.0031 | Q10: 01.11.2024 | R10: 160.13 | S10: 160.58 | T10: 161.06 | U10: 159.88 | V10: 5,26M | W10: 0.0017 | Y10: 01.11.2024 | Z10: 65.01 | AA10: 65.47 | AB10: 65.66 | AC10: 64.89 | AD10: 12,16M | AE10: -0.0046
A11: 04.11.2024 | B11: 41794.6 | C11: 42004.66 | D11: 42035.87 | E11: 41647.3 | F11: 341,51M | G11: -0.0061 | I11: 04.11.2024 | J11: 291.85 | K11: 291.55 | L11: 293.15 | M11: 290.76 | N11: 4,28M | O11: 0.0038 | Q11: 04.11.2024 | R11: 158.24 | S11: 159.7 | T11: 160.28 | U11: 158.07 | V11: 4,64M | W11: -0.0118 | Y11: 04.11.2024 | Z11: 65.11 | AA11: 65.08 | AB11: 65.42 | AC11: 64.65 | AD11: 10,98M | AE11: 0.0015
A12: 05.11.2024 | B12: 42221.88 | C12: 41835.49 | D12: 42258.84 | E12: 41766.96 | F12: 284,00M | G12: 0.0102 | I12: 05.11.2024 | J12: 293.29 | K12: 291.71 | L12: 294.78 | M12: 291.58 | N12: 3,75M | O12: 0.0049 | Q12: 05.11.2024 | R12: 158.35 | S12: 157.67 | T12: 158.59 | U12: 156.35 | V12: 6,55M | W12: 0.0007 | Y12: 05.11.2024 | Z12: 65.37 | AA12: 64.64 | AB12: 65.47 | AC12: 64.64 | AD12: 8,78M | AE12: 0.004
A13: 06.11.2024 | B13: 43729.93 | C13: 42850.4 | D13: 43778.78 | E13: 42850.4 | F13: 555,81M | G13: 0.0357 | I13: 06.11.2024 | J13: 307.4 | K13: 306.32 | L13: 309 | M13: 302.82 | N13: 10,32M | O13: 0.0481 | Q13: 06.11.2024 | R13: 157.88 | S13: 159.9 | T13: 160.85 | U13: 157.35 | V13: 8,93M | W13: -0.003 | Y13: 06.11.2024 | Z13: 63.7 | AA13: 64.42 | AB13: 64.86 | AC13: 63.18 | AD13: 22,90M | AE13: -0.0255
A14: 07.11.2024 | B14: 43729.34 | C14: 43718.92 | D14: 43823.1 | E14: 43641.92 | F14: 437,52M | G14: 0 | I14: 07.11.2024 | J14: 305.8 | K14: 307.5 | L14: 307.63 | M14: 304.42 | N14: 6,24M | O14: -0.0052 | Q14: 07.11.2024 | R14: 156.73 | S14: 158.47 | T14: 158.75 | U14: 156.51 | V14: 7,52M | W14: -0.0073 | Y14: 07.11.2024 | Z14: 63.66 | AA14: 64.29 | AB14: 64.39 | AC14: 63.6 | AD14: 14,86M | AE14: -0.0006
... A46: 24.12.2024 | B46: 43297.03 | C46: 42916.48 | D46: 43297.65 | E46: 42871.76 | F46: 230,41M | G46: 0.0091 | I46: 24.12.2024 | J46: 320.65 | K46: 318.17 | L46: 321.54 | M46: 317.28 | N46: 2,68M | O46: 0.0108 | Q46: 24.12.2024 | R46: 145.85 | S46: 145 | T46: 145.85 | U46: 144.33 | V46: 3,16M | W46: 0.004 | Y46: 24.12.2024 | Z46: 62.84 | AA46: 62.2 | AB46: 62.84 | AC46: 62.01 | AD46: 5,02M | AE46: 0.0074
A47: 25.12.2024 | B47: 43297.03 | C47: 42916.48 | D47: 43297.65 | E47: 42871.76 | G47: 0 | I47: 26.12.2024 | J47: 320.91 | K47: 319.77 | L47: 321.45 | M47: 319.46 | N47: 2,86M | O47: 0.0008 | Q47: 26.12.2024 | R47: 145.58 | S47: 145.51 | T47: 146.37 | U47: 145.09 | V47: 4,66M | W47: -0.0019 | Y47: 26.12.2024 | Z47: 62.57 | AA47: 62.62 | AB47: 62.74 | AC47: 62.4 | AD47: 7,95M | AE47: -0.0043
A48: 26.12.2024 | B48: 43325.8 | C48: 43201.85 | D48: 43373.98 | E48: 43115.09 | F48: 270,36M | G48: 0.0007 | I48: 27.12.2024 | J48: 318.66 | K48: 319.27 | L48: 321.5 | M48: 317.56 | N48: 3,49M | O48: -0.007 | Q48: 27.12.2024 | R48: 145.05 | S48: 144.87 | T48: 146.6 | U48: 144.68 | V48: 5,59M | W48: -0.0036 | Y48: 27.12.2024 | Z48: 62.45 | AA48: 62.45 | AB48: 62.95 | AC48: 62.21 | AD48: 8,54M | AE48: -0.0019
A49: 27.12.2024 | B49: 42992.21 | C49: 43142.37 | D49: 43238.85 | E49: 42761.56 | F49: 376,96M | G49: -0.0077 | I49: 30.12.2024 | J49: 315.31 | K49: 314.68 | L49: 317.11 | M49: 313.23 | N49: 3,48M | O49: -0.0105 | Q49: 30.12.2024 | R49: 143.34 | S49: 144.84 | T49: 144.88 | U49: 142.95 | V49: 6,27M | W49: -0.0118 | Y49: 30.12.2024 | Z49: 62.03 | AA49: 62.34 | AB49: 62.34 | AC49: 61.68 | AD49: 8,97M | AE49: -0.0067
A50: 30.12.2024 | B50: 42573.73 | C50: 42863.86 | D50: 42863.86 | E50: 42263.51 | F50: 383,30M | G50: -0.0097 | I50: 31.12.2024 | J50: 316.04 | K50: 316.12 | L50: 317.66 | M50: 315.19 | N50: 3,96M | O50: 0.0023 | Q50: 31.12.2024 | R50: 144.62 | S50: 143.76 | T50: 144.67 | U50: 143.31 | V50: 5,81M | W50: 0.0089 | Y50: 31.12.2024 | Z50: 62.26 | AA50: 62.02 | AB50: 62.43 | AC50: 61.8 | AD50: 9,26M | AE50: 0.0037
A51: 31.12.2024 | B51: 42544.22 | C51: 42636.7 | D51: 42779.69 | E51: 42421.29 | F51: 359,22M | G51: -0.0007 | I51: 02.01.2025 | J51: 314.4 | K51: 317.78 | L51: 319.68 | M51: 312.41 | N51: 5,37M | O51: -0.0052 | Q51: 02.01.2025 | R51: 144.02 | S51: 145.23 | T51: 145.77 | U51: 143.78 | V51: 6,05M | W51: -0.0041 | Y51: 02.01.2025 | Z51: 61.84 | AA51: 62.35 | AB51: 62.75 | AC51: 61.62 | AD51: 12,99M | AE51: -0.0067
A52: 02.01.2025 | B52: 42392.27 | C52: 42660.09 | D52: 42905.09 | E52: 42174.8 | F52: 459,86M | G52: -0.0036 | I52: 03.01.2025 | J52: 314.91 | K52: 314.18 | L52: 315.92 | M52: 312.01 | N52: 4,27M | O52: 0.0016 | Q52: 03.01.2025 | R52: 144.19 | S52: 144.07 | T52: 144.57 | U52: 143.62 | V52: 5,88M | W52: 0.0012 | Y52: 03.01.2025 | Z52: 61.75 | AA52: 61.9 | AB52: 62.08 | AC52: 61.62 | AD52: 10,40M | AE52: -0.0015
A53: 03.01.2025 | B53: 42732.13 | C53: 42495.76 | D53: 42782.76 | E53: 42436.92 | F53: 455,82M | G53: 0.008 | I53: 06.01.2025 | J53: 313.04 | K53: 315.01 | L53: 315.39 | M53: 312.07 | N53: 6,57M | O53: -0.0059 | Q53: 06.01.2025 | R53: 143.66 | S53: 143.51 | T53: 144.82 | U53: 142.93 | V53: 7,91M | W53: -0.0037 | Y53: 06.01.2025 | Z53: 60.81 | AA53: 61.5 | AB53: 61.56 | AC53: 60.66 | AD53: 17,92M | AE53: -0.0152
A54: 06.01.2025 | B54: 42706.56 | C54: 42835.52 | D54: 43115.31 | E54: 42611.16 | F54: 557,04M | G54: -0.0006 | I54: 07.01.2025 | J54: 311.67 | K54: 312.89 | L54: 315.19 | M54: 311.32 | N54: 4,96M | O54: -0.0044 | Q54: 07.01.2025 | R54: 146.23 | S54: 143.76 | T54: 147.18 | U54: 143.59 | V54: 8,42M | W54: 0.0179 | Y54: 07.01.2025 | Z54: 60.84 | AA54: 61.11 | AB54: 61.72 | AC54: 60.62 | AD54: 17,80M | AE54: 0.0005
A55: 07.01.2025 | B55: 42528.36 | C55: 42809.71 | D55: 42931.54 | E55: 42380.75 | F55: 621,64M | G55: -0.0042 | I55: 08.01.2025 | J55: 312.6 | K55: 311 | L55: 314.04 | M55: 310.21 | N55: 5,16M | O55: 0.003 | Q55: 08.01.2025 | R55: 142.27 | S55: 145.49 | T55: 145.59 | U55: 141.44 | V55: 11,18M | W55: -0.0271 | Y55: 08.01.2025 | Z55: 61.71 | AA55: 60.99 | AB55: 61.77 | AC55: 60.93 | AD55: 14,41M | AE55: 0.0143
A56: 08.01.2025 | B56: 42635.2 | C56: 42542.1 | D56: 42656.22 | E56: 42327.79 | F56: 463,43M | G56: 0.0025 | I56: 10.01.2025 | J56: 307.71 | K56: 311.2 | L56: 311.85 | M56: 305.99 | N56: 6,66M | O56: -0.0156 | Q56: 10.01.2025 | R56: 142.06 | S56: 141 | T56: 143.67 | U56: 140.68 | V56: 8,82M | W56: -0.0015 | Y56: 10.01.2025 | Z56: 61.07 | AA56: 61.58 | AB56: 61.65 | AC56: 60.73 | AD56: 22,42M | AE56: -0.0104
A57: 10.01.2025 | B57: 41938.45 | C57: 42540.29 | D57: 42540.29 | E57: 41877.3 | F57: 543,82M | G57: -0.0163 | I57: 13.01.2025 | J57: 306.92 | K57: 305 | L57: 306.92 | M57: 303.84 | N57: 9,57M | O57: -0.0026 | Q57: 13.01.2025 | R57: 144.47 | S57: 142.98 | T57: 145.07 | U57: 142.31 | V57: 10,38M | W57: 0.017 | Y57: 13.01.2025 | Z57: 61.65 | AA57: 61.13 | AB57: 61.85 | AC57: 60.71 | AD57: 18,02M | AE57: 0.0095
A58: 13.01.2025 | B58: 42297.12 | C58: 41924.68 | D58: 42319.6 | E58: 41844.89 | F58: 500,20M | G58: 0.0086 | I58: 14.01.2025 | J58: 309.09 | K58: 308.75 | L58: 310.16 | M58: 307.52 | N58: 5,11M | O58: 0.0071 | Q58: 14.01.2025 | R58: 144.75 | S58: 144.5 | T58: 144.81 | U58: 142.86 | V58: 8,68M | W58: 0.0019 | Y58: 14.01.2025 | Z58: 62.04 | AA58: 61.65 | AB58: 62.06 | AC58: 61.3 | AD58: 16,66M | AE58: 0.0063
A59: 14.01.2025 | B59: 42518.28 | C59: 42366.42 | D59: 42544.57 | E59: 42157.03 | F59: 454,66M | G59: 0.0052 | I59: 15.01.2025 | J59: 316.28 | K59: 313.68 | L59: 317.19 | M59: 313.13 | N59: 5,22M | O59: 0.0233 | Q59: 15.01.2025 | R59: 144.97 | S59: 145.31 | T59: 146.05 | U59: 144.26 | V59: 7,43M | W59: 0.0015 | Y59: 15.01.2025 | Z59: 61.77 | AA59: 62.33 | AB59: 62.62 | AC59: 61.68 | AD59: 16,19M | AE59: -0.0044
... A252: 21.10.2025 | B252: 46924.74 | C252: 46707.08 | D252: 47125.66 | E252: 46688.25 | F252: 436,74M | G252: 0.0047 | I252: 22.10.2025 | J252: 345.36 | K252: 347.82 | L252: 348.17 | M252: 344.5 | N252: 5,07M | O252: -0.0053 | Q252: 22.10.2025 | R252: 192.94 | S252: 192 | T252: 193.45 | U252: 191.77 | V252: 6,34M | W252: 0.0055 | Y252: 22.10.2025 | Z252: 70.81 | AA252: 71.36 | AB252: 71.61 | AC252: 70.51 | AD252: 18,29M | AE252: -0.0058
A253: 22.10.2025 | B253: 46590.41 | C253: 46941.56 | D253: 46941.56 | E253: 46461.52 | F253: 458,46M | G253: -0.0071

Sheet NASDAQ
C1: NASDAQ | K1: AAPL | S1: TSLA | AA1: MSFT
A2: Ημ/νία | B2: Τελευταία | C2: Άνοιγμα | D2: Υψηλό | E2: Χαμηλό | F2: Όγκος | G2: Αλλ.% | I2: Ημ/νία | J2: Τελευταία | K2: Άνοιγμα | L2: Υψηλό | M2: Χαμηλό | N2: Όγκος | O2: Αλλ.% | Q2: Ημ/νία | R2: Τελευταία | S2: Άνοιγμα | T2: Υψηλό | U2: Χαμηλό | V2: Όγκος | W2: Αλλ.% | Y2: Ημ/νία | Z2: Τελευταία | AA2: Άνοιγμα | AB2: Υψηλό | AC2: Χαμηλό | AD2: Όγκος | AE2: Αλλ.%
A3: 23.10.2024 | B3: 18276.65 | C3: 18502.06 | D3: 18509.19 | E3: 18146.61 | F3: 1,02B | G3: -0.016 | I3: 23.10.2024 | J3: 230.76 | K3: 234.08 | L3: 235.14 | M3: 227.76 | N3: 52,29M | O3: -0.0216 | Q3: 23.10.2024 | R3: 213.65 | S3: 217.13 | T3: 218.72 | U3: 212.11 | V3: 80,94M | W3: -0.0198 | Y3: 23.10.2024 | Z3: 424.6 | AA3: 430.86 | AB3: 431.08 | AC3: 422.53 | AD3: 19,65M | AE3: -0.0068
A4: 24.10.2024 | B4: 18415.49 | C4: 18384.15 | D4: 18435.37 | E4: 18305.42 | F4: 977,77M | G4: 0.0076 | I4: 24.10.2024 | J4: 230.57 | K4: 229.98 | L4: 230.82 | M4: 228.41 | N4: 31,11M | O4: -0.0008 | Q4: 24.10.2024 | R4: 260.48 | S4: 244.68 | T4: 262.12 | U4: 242.65 | V4: 204,49M | W4: 0.2192 | Y4: 24.10.2024 | Z4: 424.73 | AA4: 425.33 | AB4: 425.98 | AC4: 422.4 | AD4: 13,58M | AE4: 0.0003
A5: 25.10.2024 | B5: 18518.61 | C5: 18512.58 | D5: 18690.01 | E5: 18487.06 | F5: 976,29M | G5: 0.0056 | I5: 25.10.2024 | J5: 231.41 | K5: 229.74 | L5: 233.22 | M5: 229.57 | N5: 38,80M | O5: 0.0036 | Q5: 25.10.2024 | R5: 269.19 | S5: 256.01 | T5: 269.49 | U5: 255.32 | V5: 161,61M | W5: 0.0334 | Y5: 25.10.2024 | Z5: 428.15 | AA5: 426.76 | AB5: 432.52 | AC5: 426.57 | AD5: 16,90M | AE5: 0.0081
A6: 28.10.2024 | B6: 18567.19 | C6: 18648.25 | D6: 18671.01 | E6: 18563.02 | F6: 1,03B | G6: 0.0026 | I6: 28.10.2024 | J6: 233.4 | K6: 233.32 | L6: 234.73 | M6: 232.55 | N6: 36,09M | O6: 0.0086 | Q6: 28.10.2024 | R6: 262.51 | S6: 270 | T6: 273.54 | U6: 262.24 | V6: 107,65M | W6: -0.0248 | Y6: 28.10.2024 | Z6: 426.59 | AA6: 431.65 | AB6: 431.94 | AC6: 426.3 | AD6: 14,88M | AE6: -0.0036
A7: 29.10.2024 | B7: 18712.75 | C7: 18576.09 | D7: 18753.19 | E7: 18509.59 | F7: 1,12B | G7: 0.0078 | I7: 29.10.2024 | J7: 233.67 | K7: 233.1 | L7: 234.32 | M7: 232.32 | N7: 35,42M | O7: 0.0012 | Q7: 29.10.2024 | R7: 259.52 | S7: 264.51 | T7: 264.98 | U7: 255.51 | V7: 80,52M | W7: -0.0114 | Y7: 29.10.2024 | Z7: 431.95 | AA7: 428 | AB7: 433.17 | AC7: 425.8 | AD7: 17,64M | AE7: 0.0126
A8: 30.10.2024 | B8: 18607.93 | C8: 18731.69 | D8: 18785.49 | E8: 18598.24 | F8: 1,16B | G8: -0.0056 | I8: 30.10.2024 | J8: 230.1 | K8: 232.61 | L8: 233.47 | M8: 229.55 | N8: 47,07M | O8: -0.0153 | Q8: 30.10.2024 | R8: 257.55 | S8: 258.04 | T8: 263.35 | U8: 255.82 | V8: 53,99M | W8: -0.0076 | Y8: 30.10.2024 | Z8: 432.53 | AA8: 437.43 | AB8: 438.5 | AC8: 432.1 | AD8: 29,75M | AE8: 0.0013
A9: 31.10.2024 | B9: 18095.15 | C9: 18427.31 | D9: 18427.31 | E9: 18083.95 | F9: 1,31B | G9: -0.0276 | I9: 31.10.2024 | J9: 225.91 | K9: 229.34 | L9: 229.83 | M9: 225.37 | N9: 64,37M | O9: -0.0182 | Q9: 31.10.2024 | R9: 249.85 | S9: 257.99 | T9: 259.75 | U9: 249.25 | V9: 66,58M | W9: -0.0299 | Y9: 31.10.2024 | Z9: 406.35 | AA9: 415.36 | AB9: 416.16 | AC9: 406.3 | AD9: 53,97M | AE9: -0.0605
A10: 01.11.2024 | B10: 18239.92 | C10: 18189.67 | D10: 18363.94 | E10: 18181.53 | F10: 1,05B | G10: 0.008 | I10: 01.11.2024 | J10: 222.91 | K10: 220.96 | L10: 225.35 | M10: 220.27 | N10: 65,28M | O10: -0.0133 | Q10: 01.11.2024 | R10: 248.98 | S10: 252.04 | T10: 254 | U10: 246.63 | V10: 57,55M | W10: -0.0035 | Y10: 01.11.2024 | Z10: 410.37 | AA10: 409.01 | AB10: 415.5 | AC10: 407.5 | AD10: 24,23M | AE10: 0.0099
A11: 04.11.2024 | B11: 18179.98 | C11: 18220.43 | D11: 18308.3 | E11: 18112.83 | F11: 1,04B | G11: -0.0033 | I11: 04.11.2024 | J11: 222.01 | K11: 220.99 | L11: 222.79 | M11: 219.71 | N11: 44,94M | O11: -0.004 | Q11: 04.11.2024 | R11: 242.84 | S11: 244.56 | T11: 248.9 | U11: 238.88 | V11: 68,80M | W11: -0.0247 | Y11: 04.11.2024 | Z11: 408.46 | AA11: 409.8 | AB11: 410.42 | AC11: 405.57 | AD11: 19,67M | AE11: -0.0047
A12: 05.11.2024 | B12: 18439.17 | C12: 18250.71 | D12: 18449.68 | E12: 18250.71 | F12: 1,07B | G12: 0.0143 | I12: 05.11.2024 | J12: 223.45 | K12: 221.79 | L12: 223.95 | M12: 221.14 | N12: 28,11M | O12: 0.0065 | Q12: 05.11.2024 | R12: 251.44 | S12: 247.34 | T12: 255.28 | U12: 246.21 | V12: 69,28M | W12: 0.0354 | Y12: 05.11.2024 | Z12: 411.46 | AA12: 408.37 | AB12: 414.9 | AC12: 408.08 | AD12: 17,63M | AE12: 0.0073
A13: 06.11.2024 | B13: 18983.46 | C13: 18772.76 | D13: 19000.5 | E13: 18730.21 | F13: 1,64B | G13: 0.0295 | I13: 06.11.2024 | J13: 222.72 | K13: 222.61 | L13: 226.07 | M13: 221.19 | N13: 54,56M | O13: -0.0033 | Q13: 06.11.2024 | R13: 288.53 | S13: 284.67 | T13: 289.59 | U13: 275.62 | V13: 165,23M | W13: 0.1475 | Y13: 06.11.2024 | Z13: 420.18 | AA13: 412.42 | AB13: 420.45 | AC13: 410.52 | AD13: 26,68M | AE13: 0.0212
A14: 07.11.2024 | B14: 19269.46 | C14: 19084.43 | D14: 19301.7 | E14: 19084.43 | F14: 1,43B | G14: 0.0151 | I14: 07.11.2024 | J14: 227.48 | K14: 224.63 | L14: 227.88 | M14: 224.57 | N14: 42,14M | O14: 0.0214 | Q14: 07.11.2024 | R14: 296.91 | S14: 288.89 | T14: 299.75 | U14: 285.52 | V14: 117,31M | W14: 0.029 | Y14: 07.11.2024 | Z14: 425.43 | AA14: 421.28 | AB14: 426.85 | AC14: 419.88 | AD14: 19,90M | AE14: 0.0125
... A252: 22.10.2025 | B252: 22740.4 | C252: 22940.79 | D252: 22978.4 | E252: 22514.08 | F252: 2,06B | G252: -0.0093 | I252: 22.10.2025 | J252: 258.45 | K252: 262.65 | L252: 262.85 | M252: 255.43 | N252: 45,02M | O252: -0.0164 | Q252: 22.10.2025 | R252: 438.97 | S252: 443.45 | T252: 445.54 | U252: 429 | V252: 84,02M | W252: -0.0082 | Y252: 22.10.2025 | Z252: 520.54 | AA252: 521.15 | AB252: 525.23 | AC252: 517.71 | AD252: 18,96M | AE252: 0.0056

Sheet USA Ret
B1: ΑΠΟΔΟΣΕΙΣ(RETURNS)
B2: ΜΕΤΟΧΕΣ | C2: ΜΕΤΟΧΕΣ | D2: ΜΕΤΟΧΕΣ | E2: ΜΕΤΟΧΕΣ | F2: ΜΕΤΟΧΕΣ | G2: ΜΕΤΟΧΕΣ | H2: ΜΕΤΟΧΕΣ | I2: ΜΕΤΟΧΕΣ
A3: Trade Date | B3: DOW JONES | C3: V | D3: JNJ | E3: KO | F3: AAPL | G3: TSLA | H3: MSFT | I3: NASDAQ
A5: 24.10.2024 | B5: =LN(NYSE!B4/NYSE!B3) -> -0.0033123164 | C5: =LN(NYSE!J4/NYSE!J3) -> -0.0019048297 | D5: =LN(NYSE!R4/NYSE!R3) -> -0.013291854 | E5: =LN(NYSE!Z4/NYSE!Z3) -> -0.010494517 | F5: =LN(NASDAQ!J4/NASDAQ!J3) -> -0.00082370542 | G5: =LN(NASDAQ!R4/NASDAQ!R3) -> 0.19818692 | H5: =LN(NASDAQ!Z4/NASDAQ!Z3) -> 0.00030612365 | I5: =LN(NASDAQ!B4/NASDAQ!B3) -> 0.0075678694
A6: 25.10.2024 | B6: =LN(NYSE!B5/NYSE!B4) -> -0.0061537374 | C6: =LN(NYSE!J5/NYSE!J4) -> -0.0052748153 | D6: =LN(NYSE!R5/NYSE!R4) -> -0.01719346 | E6: =LN(NYSE!Z5/NYSE!Z4) -> -0.0056623605 | F6: =LN(NASDAQ!J5/NASDAQ!J4) -> 0.0036365251 | G6: =LN(NASDAQ!R5/NASDAQ!R4) -> 0.032891367 | H6: =LN(NASDAQ!Z5/NASDAQ!Z4) -> 0.0080199286 | I6: =LN(NASDAQ!B5/NASDAQ!B4) -> 0.0055840141 | L6: ΜΕΤΡΑ ΑΠΟΔΟΣΗΣ ΚΑΙ ΚΙΝΔΥΝΟΥ | N6: DOW JONES | O6: V | P6: JNJ | Q6: KO | R6: AAPL | S6: TSLA | T6: MSFT | U6: NASDAQ
A7: 28.10.2024 | B7: =LN(NYSE!B6/NYSE!B5) -> 0.0064654339 | C7: =LN(NYSE!J6/NYSE!J5) -> 0.0086938631 | D7: =LN(NYSE!R6/NYSE!R5) -> 0.0044654006 | E7: =LN(NYSE!Z6/NYSE!Z5) -> -0.0037427995 | F7: =LN(NASDAQ!J6/NASDAQ!J5) -> 0.0085626908 | G7: =LN(NASDAQ!R6/NASDAQ!R5) -> -0.025128273 | H7: =LN(NASDAQ!Z6/NASDAQ!Z5) -> -0.0036502369 | I7: =LN(NASDAQ!B6/NASDAQ!B5) -> 0.0026198722 | K7: 1 | L7: ΜΕΣΗ ΑΠΟΔΟΣΗ | M7: μ | N7: =AVERAGE(B5:B253) -> 0.00039634242 | O7: =AVERAGE(C5:C253) -> 0.00078899012 | P7: =AVERAGE(D5:D253) -> 0.00060737028 | Q7: =AVERAGE(E5:E253) -> 0.00016203004 | R7: =AVERAGE(F5:F253) -> 0.00045511664 | S7: =AVERAGE(G5:G253) -> 0.0028919354 | T7: =AVERAGE(H5:H253) -> 0.00081814934 | U7: =AVERAGE(I5:I253) -> 0.0008775855
A8: 29.10.2024 | B8: =LN(NYSE!B7/NYSE!B6) -> -0.003652069 | C8: =LN(NYSE!J7/NYSE!J6) -> -0.0081615801 | D8: =LN(NYSE!R7/NYSE!R6) -> -0.009387989 | E8: =LN(NYSE!Z7/NYSE!Z6) -> -0.016789323 | F8: =LN(NASDAQ!J7/NASDAQ!J6) -> 0.0011561437 | G8: =LN(NASDAQ!R7/NASDAQ!R6) -> -0.011455406 | H8: =LN(NASDAQ!Z7/NASDAQ!Z6) -> 0.012486476 | I8: =LN(NASDAQ!B7/NASDAQ!B6) -> 0.0078090651 | L8: ΔΙΑΚΥΜΑΝΣΗ | M8: σ^2 | N8: =VARP(B5:B253) -> 0.0001138843 | O8: =VARP(C5:C253) -> 0.00019870188 | P8: =VARP(D5:D253) -> 0.00014920758 | Q8: =VARP(E5:E253) -> 0.0001210824 | R8: =VARP(F5:F253) -> 0.00041554757 | S8: =VARP(G5:G253) -> 0.0019409976 | T8: =VARP(H5:H253) -> 0.00023821959 | U8: =VARP(I5:I253) -> 0.00023329294 | V8: ΣΥΝΟΛΙΚΟΣ ΚΙΝΔΥΝΟΣ
A9: 30.10.2024 | B9: =LN(NYSE!B8/NYSE!B7) -> -0.0021691373 | C9: =LN(NYSE!J8/NYSE!J7) -> 0.028951047 | D9: =LN(NYSE!R8/NYSE!R7) -> 0.003242909 | E9: =LN(NYSE!Z8/NYSE!Z7) -> 0.0054761317 | F9: =LN(NASDAQ!J8/NASDAQ!J7) -> -0.015395867 | G9: =LN(NASDAQ!R8/NASDAQ!R7) -> -0.0076198949 | H9: =LN(NASDAQ!Z8/NASDAQ!Z7) -> 0.0013418473 | I9: =LN(NASDAQ!B8/NASDAQ!B7) -> -0.0056172758 | L9: ΤΥΠΙΚΗ ΑΠΟΚΛΙΣΗ | M9: σ | N9: =SQRT(N8) -> 0.010671659 | O9: =SQRT(O8) -> 0.014096166 | P9: =SQRT(P8) -> 0.012215056 | Q9: =SQRT(Q8) -> 0.011003745 | R9: =SQRT(R8) -> 0.020384984 | S9: =SQRT(S8) -> 0.044056755 | T9: =SQRT(T8) -> 0.015434364 | U9: =SQRT(U8) -> 0.01527393
A10: 31.10.2024 | B10: =LN(NYSE!B9/NYSE!B8) -> -0.009012158 | C10: =LN(NYSE!J9/NYSE!J8) -> -0.0010689472 | D10: =LN(NYSE!R9/NYSE!R8) -> -0.0046806339 | E10: =LN(NYSE!Z9/NYSE!Z8) -> -0.0092967217 | F10: =LN(NASDAQ!J9/NASDAQ!J8) -> -0.018377307 | G10: =LN(NASDAQ!R9/NASDAQ!R8) -> -0.030353138 | H10: =LN(NASDAQ!Z9/NASDAQ!Z8) -> -0.062436831 | I10: =LN(NASDAQ!B9/NASDAQ!B8) -> -0.027943887
A11: 01.11.2024 | B11: =LN(NYSE!B10/NYSE!B9) -> 0.0068896714 | C11: =LN(NYSE!J10/NYSE!J9) -> 0.0030658492 | D11: =LN(NYSE!R10/NYSE!R9) -> 0.0016875531 | E11: =LN(NYSE!Z10/NYSE!Z9) -> -0.0046040597 | F11: =LN(NASDAQ!J10/NASDAQ!J9) -> -0.013368587 | G11: =LN(NASDAQ!R10/NASDAQ!R9) -> -0.0034881658 | H11: =LN(NASDAQ!Z10/NASDAQ!Z9) -> 0.0098443346 | I11: =LN(NASDAQ!B10/NASDAQ!B9) -> 0.0079686521 | L11: ΣΥΝΤΕΛΕΣΤΗΣ ΜΕΤΑΒΛΗΤΟΤΗΤΑΣ | M11: σ/μ | N11: =N9/N7 -> 26.925351 | O11: =O9/O7 -> 17.866086 | P11: =P9/P7 -> 20.111382 | Q11: =Q9/Q7 -> 67.911756 | R11: =R9/R7 -> 44.790681 | S11: =S9/S7 -> 15.23435 | T11: =T9/T7 -> 18.864971 | U11: =U9/U7 -> 17.404492
A12: 04.11.2024 | B12: =LN(NYSE!B11/NYSE!B10) -> -0.0061443213 | C12: =LN(NYSE!J11/NYSE!J10) -> 0.0038105747 | D12: =LN(NYSE!R11/NYSE!R10) -> -0.011873117 | E12: =LN(NYSE!Z11/NYSE!Z10) -> 0.001537043 | F12: =LN(NASDAQ!J11/NASDAQ!J10) -> -0.0040456767 | G12: =LN(NASDAQ!R11/NASDAQ!R10) -> -0.024969782 | H12: =LN(NASDAQ!Z11/NASDAQ!Z10) -> -0.0046652015 | I12: =LN(NASDAQ!B11/NASDAQ!B10) -> -0.00329161
A13: 05.11.2024 | B13: =LN(NYSE!B12/NYSE!B11) -> 0.010171426 | C13: =LN(NYSE!J12/NYSE!J11) -> 0.004921909 | D13: =LN(NYSE!R12/NYSE!R11) -> 0.00069490511 | E13: =LN(NYSE!Z12/NYSE!Z11) -> 0.0039852904 | F13: =LN(NASDAQ!J12/NASDAQ!J11) -> 0.0064652495 | G13: =LN(NASDAQ!R12/NASDAQ!R11) -> 0.034801602 | H13: =LN(NASDAQ!Z12/NASDAQ!Z11) -> 0.0073178198 | I13: =LN(NASDAQ!B12/NASDAQ!B11) -> 0.014156218 | K13: 2 | L13: α ΜΕΤΟΧΗΣ | O13: =INTERCEPT(C5:C253,$B$5:$B$253) -> 0.00075346158 | P13: =INTERCEPT(D5:D253,$B$5:$B$253) -> 0.0006372648 | Q13: =INTERCEPT(E5:E253,$B$5:$B$253) -> 0.0001286993 | R13: =INTERCEPT(F5:F253,$I$5:$I$253) -> -0.00040415684 | S13: =INTERCEPT(G5:G253,$I$5:$I$253) -> 0.0011781038 | T13: =INTERCEPT(H5:H253,$I$5:$I$253) -> 0.00013235951
A14: 06.11.2024 | B14: =LN(NYSE!B13/NYSE!B12) -> 0.035094195 | C14: =LN(NYSE!J13/NYSE!J12) -> 0.04698795 | D14: =LN(NYSE!R13/NYSE!R12) -> -0.0029725222 | E14: =LN(NYSE!Z13/NYSE!Z12) -> -0.025878875 | F14: =LN(NASDAQ!J13/NASDAQ!J12) -> -0.0032722982 | G14: =LN(NASDAQ!R13/NASDAQ!R12) -> 0.13759467 | H14: =LN(NASDAQ!Z13/NASDAQ!Z12) -> 0.020971381 | I14: =LN(NASDAQ!B13/NASDAQ!B12) -> 0.029090867 | L14: β ΜΕΤΟΧΗΣ | O14: =SLOPE(C5:C253,$B$5:$B$253) -> 0.08964102 | P14: =SLOPE(D5:D253,$B$5:$B$253) -> -0.075425974 | Q14: =SLOPE(E5:E253,$B$5:$B$253) -> 0.084095835 | R14: =SLOPE(F5:F253,$I$5:$I$253) -> 0.97913362 | S14: =SLOPE(G5:G253,$I$5:$I$253) -> 1.9528942 | T14: =SLOPE(H5:H253,$I$5:$I$253) -> 0.78145073 | V14: ΣΥΣΤΗΜΑΤΙΚΟΣ ΚΙΝΔΥΝΟΣ
A15: 07.11.2024 | B15: =LN(NYSE!B14/NYSE!B13) -> -1.3491995e-05 | C15: =LN(NYSE!J14/NYSE!J13) -> -0.0052185376 | D15: =LN(NYSE!R14/NYSE!R13) -> -0.0073106711 | E15: =LN(NYSE!Z14/NYSE!Z13) -> -0.00062814072 | F15: =LN(NASDAQ!J14/NASDAQ!J13) -> 0.021146945 | G15: =LN(NASDAQ!R14/NASDAQ!R13) -> 0.028629996 | H15: =LN(NASDAQ!Z14/NASDAQ!Z13) -> 0.012417231 | I15: =LN(NASDAQ!B14/NASDAQ!B13) -> 0.014953385
A16: 08.11.2024 | B16: =LN(NYSE!B15/NYSE!B14) -> 0.0059201026 | C16: =LN(NYSE!J15/NYSE!J14) -> 0.0067463225 | D16: =LN(NYSE!R15/NYSE!R14) -> -0.0080717927 | E16: =LN(NYSE!Z15/NYSE!Z14) -> 0.0040758796 | F16: =LN(NASDAQ!J15/NASDAQ!J14) -> -0.0022885319 | G16: =LN(NASDAQ!R15/NASDAQ!R14) -> 0.078697184 | H16: =LN(NASDAQ!Z15/NASDAQ!Z14) -> -0.0068163053 | I16: =LN(NASDAQ!B15/NASDAQ!B14) -> 0.00089842792 | L16: ΗΜΕΡΕΣ ΣΤΟ ΕΤΟΣ | N16: =COUNT(B5:B253) -> 249 | O16: =COUNT(C5:C253) -> 249 | P16: =COUNT(D5:D253) -> 249 | Q16: =COUNT(E5:E253) -> 249 | R16: =COUNT(F5:F253) -> 249 | S16: =COUNT(G5:G253) -> 249 | T16: =COUNT(H5:H253) -> 249 | U16: =COUNT(I5:I253) -> 249
A17: 11.11.2024 | B17: =LN(NYSE!B16/NYSE!B15) -> 0.0068902107 | C17: =LN(NYSE!J16/NYSE!J15) -> 0.0098580284 | D17: =LN(NYSE!R16/NYSE!R15) -> -0.0027696388 | E17: =LN(NYSE!Z16/NYSE!Z15) -> -0.008799554 | F17: =LN(NASDAQ!J16/NASDAQ!J15) -> -0.01210148 | G17: =LN(NASDAQ!R16/NASDAQ!R15) -> 0.085806908 | H17: =LN(NASDAQ!Z16/NASDAQ!Z15) -> -0.010778761 | I17: =LN(NASDAQ!B16/NASDAQ!B15) -> 0.00062095803 | L17: ΑΠΟΔΟΣΗ ΣΕ ΕΤΗΣΙΑ ΒΑΣΗ
A18: 12.11.2024 | B18: =LN(NYSE!B17/NYSE!B16) -> -0.0086651833 | C18: =LN(NYSE!J17/NYSE!J16) -> -0.003447335 | D18: =LN(NYSE!R17/NYSE!R16) -> -0.01560094 | E18: =LN(NYSE!Z17/NYSE!Z16) -> -0.0025284464 | F18: =LN(NASDAQ!J17/NASDAQ!J16) -> 0 | G18: =LN(NASDAQ!R17/NASDAQ!R16) -> -0.063426758 | H18: =LN(NASDAQ!Z17/NASDAQ!Z16) -> 0.011937743 | I18: =LN(NASDAQ!B17/NASDAQ!B16) -> -0.00089994449 | L18: (1+R)=(1+R/m)mn
A19: 13.11.2024 | B19: =LN(NYSE!B18/NYSE!B17) -> 0.0010745522 | C19: =LN(NYSE!J18/NYSE!J17) -> -0.0011948397 | D19: =LN(NYSE!R18/NYSE!R17) -> 0.0039231121 | E19: =LN(NYSE!Z18/NYSE!Z17) -> -0.0031695748 | F19: =LN(NASDAQ!J18/NASDAQ!J17) -> 0.0039612826 | G19: =LN(NASDAQ!R18/NASDAQ!R17) -> 0.0053132668 | H19: =LN(NASDAQ!Z18/NASDAQ!Z17) -> 0.005116548 | I19: =LN(NASDAQ!B18/NASDAQ!B17) -> -0.0026319003 | L19: R/m= Επιτόκιο περιόδου | O19: =N7 -> 0.00039634242 | P19: =O7 -> 0.00078899012 | Q19: =P7 -> 0.00060737028 | R19: =Q7 -> 0.00016203004 | S19: =R7 -> 0.00045511664 | T19: =S7 -> 0.0028919354 | U19: =T7 -> 0.00081814934
A20: 14.11.2024 | B20: =LN(NYSE!B19/NYSE!B18) -> -0.0047276851 | C20: =LN(NYSE!J19/NYSE!J18) -> -0.0039823276 | D20: =LN(NYSE!R19/NYSE!R18) -> -0.0089804281 | E20: =LN(NYSE!Z19/NYSE!Z18) -> -0.0071684895 | F20: =LN(NASDAQ!J19/NASDAQ!J18) -> 0.013676483 | G20: =LN(NASDAQ!R19/NASDAQ!R18) -> -0.05944814 | H20: =LN(NASDAQ!Z19/NASDAQ!Z18) -> 0.0039667223 | I20: =LN(NASDAQ!B19/NASDAQ!B18) -> -0.006420222 | L20: n= Αριθμός Ετών | O20: 1 | P20: 1 | Q20: 1 | R20: 1 | S20: 1 | T20: 1 | U20: 1
A21: 15.11.2024 | B21: =LN(NYSE!B20/NYSE!B19) -> -0.0070157296 | C21: =LN(NYSE!J20/NYSE!J19) -> 0.0044991903 | D21: =LN(NYSE!R20/NYSE!R19) -> 0.013927711 | E21: =LN(NYSE!Z20/NYSE!Z19) -> -0.013034218 | F21: =LN(NASDAQ!J20/NASDAQ!J19) -> -0.014209674 | G21: =LN(NASDAQ!R20/NASDAQ!R19) -> 0.030196945 | H21: =LN(NASDAQ!Z20/NASDAQ!Z19) -> -0.028247849 | I21: =LN(NASDAQ!B20/NASDAQ!B19) -> -0.022628922 | L21: m= περίοδοι ανα Ετος | O21: =N16 -> 249 | P21: =O16 -> 249 | Q21: =P16 -> 249 | R21: =Q16 -> 249 | S21: =R16 -> 249 | T21: =S16 -> 249 | U21: =T16 -> 249
A22: 18.11.2024 | B22: =LN(NYSE!B21/NYSE!B20) -> -0.0012757591 | C22: =LN(NYSE!J21/NYSE!J20) -> 0.0081055445 | D22: =LN(NYSE!R21/NYSE!R20) -> 0.0049875415 | E22: =LN(NYSE!Z21/NYSE!Z20) -> 0.0019417482 | F22: =LN(NASDAQ!J21/NASDAQ!J20) -> 0.013332942 | G22: =LN(NASDAQ!R21/NASDAQ!R20) -> 0.054664383 | H22: =LN(NASDAQ!Z21/NASDAQ!Z20) -> 0.0018296505 | I22: =LN(NASDAQ!B21/NASDAQ!B20) -> 0.0059612799 | K22: * | L22: R= [(1+R/m)mn]-1
A23: 19.11.2024 | B23: =LN(NYSE!B22/NYSE!B21) -> -0.0027847245 | C23: =LN(NYSE!J22/NYSE!J21) -> -0.0009935739 | D23: =LN(NYSE!R22/NYSE!R21) -> -0.011502223 | E23: =LN(NYSE!Z22/NYSE!Z21) -> 0.011731754 | F23: =LN(NASDAQ!J22/NASDAQ!J21) -> 0.0011396013 | G23: =LN(NASDAQ!R22/NASDAQ!R21) -> 0.021205924 | H23: =LN(NASDAQ!Z22/NASDAQ!Z21) -> 0.0048707432 | I23: =LN(NASDAQ!B22/NASDAQ!B21) -> 0.010358151 | L23: R= Ετήσια Αποδοση | O23: =(1+O19)^(O20*O16)-1 -> 0.1037017 | P23: =(1+P19)^(P20*P16)-1 -> 0.21699059 | Q23: =(1+Q19)^(Q20*Q16)-1 -> 0.16321682 | R23: =(1+R19)^(R20*R16)-1 -> 0.041167013 | S23: =(1+S19)^(S20*S16)-1 -> 0.11996593 | T23: =(1+T19)^(T20*T16)-1 -> 1.0524879 | U23: =(1+U19)^(U20*U16)-1 -> 0.22585173
A24: 20.11.2024 | B24: =LN(NYSE!B23/NYSE!B22) -> 0.0032195268 | C24: =LN(NYSE!J23/NYSE!J22) -> -0.014405003 | D24: =LN(NYSE!R23/NYSE!R22) -> 0.00071869592 | E24: =LN(NYSE!Z23/NYSE!Z22) -> 0.0063704627 | F24: =LN(NASDAQ!J23/NASDAQ!J22) -> 0.0031490579 | G24: =LN(NASDAQ!R23/NASDAQ!R22) -> -0.011540323 | H24: =LN(NASDAQ!Z23/NASDAQ!Z22) -> -0.0055203673 | I24: =LN(NASDAQ!B23/NASDAQ!B22) -> -0.0011240039
A25: 21.11.2024 | B25: =LN(NYSE!B24/NYSE!B23) -> 0.01058411 | C25: =LN(NYSE!J24/NYSE!J23) -> 0.0081323651 | D25: =LN(NYSE!R24/NYSE!R23) -> 0.015489114 | E25: =LN(NYSE!Z24/NYSE!Z23) -> 0.012150051 | F25: =LN(NASDAQ!J24/NASDAQ!J23) -> -0.0020982697 | G25: =LN(NASDAQ!R24/NASDAQ!R23) -> -0.0070122194 | H25: =LN(NASDAQ!Z24/NASDAQ!Z23) -> -0.0063257732 | I25: =LN(NASDAQ!B24/NASDAQ!B23) -> 0.00033106159
A26: 22.11.2024 | B26: =LN(NYSE!B25/NYSE!B24) -> 0.0096671996 | C26: =LN(NYSE!J25/NYSE!J24) -> 6.4534865e-05 | D26: =LN(NYSE!R25/NYSE!R24) -> -0.0021244415 | E26: =LN(NYSE!Z25/NYSE!Z24) -> 0.002506267 | F26: =LN(NASDAQ!J25/NASDAQ!J24) -> 0.0058901979 | G26: =LN(NASDAQ!R25/NASDAQ!R24) -> 0.037334587 | H26: =LN(NASDAQ!Z25/NASDAQ!Z24) -> 0.0099534484 | I26: =LN(NASDAQ!B25/NASDAQ!B24) -> 0.0016447203 | L26: ETΗΣΙΟΠOIHMENO ΣΕ ΠΕΡΙΟΔΙΚΟ | O26: =((1+O23)^(1/(O21*O20)))-1 -> 0.00039634242 | P26: =((1+P23)^(1/(P21*P20)))-1 -> 0.00078899012 | Q26: =((1+Q23)^(1/(Q21*Q20)))-1 -> 0.00060737028 | R26: =((1+R23)^(1/(R21*R20)))-1 -> 0.00016203004 | S26: =((1+S23)^(1/(S21*S20)))-1 -> 0.00045511664 | T26: =((1+T23)^(1/(T21*T20)))-1 -> 0.0028919354 | U26: =((1+U23)^(1/(U21*U20)))-1 -> 0.00081814934
A27: 25.11.2024 | B27: =LN(NYSE!B26/NYSE!B25) -> 0.009885395 | C27: =LN(NYSE!J26/NYSE!J25) -> 0.010495835 | D27: =LN(NYSE!R26/NYSE!R25) -> 0.0039234654 | E27: =LN(NYSE!Z26/NYSE!Z25) -> 0.0071707244 | F27: =LN(NASDAQ!J26/NASDAQ!J25) -> 0.012966426 | G27: =LN(NASDAQ!R26/NASDAQ!R25) -> -0.040430885 | H27: =LN(NASDAQ!Z26/NASDAQ!Z25) -> 0.0042833792 | I27: =LN(NASDAQ!B26/NASDAQ!B25) -> 0.0026900716
A28: 26.11.2024 | B28: =LN(NYSE!B27/NYSE!B26) -> 0.0027621515 | C28: =LN(NYSE!J27/NYSE!J26) -> -0.0043839369 | D28: =LN(NYSE!R27/NYSE!R26) -> -0.0081212177 | E28: =LN(NYSE!Z27/NYSE!Z26) -> 0.0026370914 | F28: =LN(NASDAQ!J27/NASDAQ!J26) -> 0.0093604428 | G28: =LN(NASDAQ!R27/NASDAQ!R26) -> -0.0010637985 | H28: =LN(NASDAQ!Z27/NASDAQ!Z26) -> 0.02173023 | I28: =LN(NASDAQ!B27/NASDAQ!B26) -> 0.006316457 | L28: ΙΣΧΥΕΙ Η ΣΧΕΣΗ
A29: 27.11.2024 | B29: =LN(NYSE!B28/NYSE!B27) -> -0.0030865473 | C29: =LN(NYSE!J28/NYSE!J27) -> 0.0091937058 | D29: =LN(NYSE!R28/NYSE!R27) -> 0.0056789001 | E29: =LN(NYSE!Z28/NYSE!Z27) -> -0.0018607541 | F29: =LN(NASDAQ!J28/NASDAQ!J27) -> -0.00055320327 | G29: =LN(NASDAQ!R28/NASDAQ!R27) -> -0.015914032 | H29: =LN(NASDAQ!Z28/NASDAQ!Z27) -> -0.011751293 | I29: =LN(NASDAQ!B28/NASDAQ!B27) -> -0.006020513
